Workbook
Name tabOSP: tbResumoR11[#All]
Name tabOSP: #REF!
Name tabOSP: tbResumoR11[#All]
Name tabOSP: #REF!
Name tabOSP: tbResumoR11[#All]
Name tabOSP: #REF!
Name tabOSP: tbResumoR11[#All]
Name tabOSP: #REF!
Name tabOSP: tbResumoR11[#All]
Name tabOSP: #REF!
Name tabOSP: tbResumoR11[#All]
Name tbContratos: 'Tabelas Auxiliares'!$D$3:$E$9
Name tbServicos: 'Tabelas Auxiliares'!$H$4:$H$60
Name tbSituacao: 'Tabelas Auxiliares'!$M$2:$M$10

Sheet DASHBOARD
B2: CONTROLE DE OSPs — LOTE 04
B3: ="Regiões 11, 12, 13, 22, 23 e 24 | "&COUNTIF('BASE DASHBOARD'!$B$4:$B$217,"?*")&" OSPs cadastradas | Atualizado em "&TEXT(TODAY(),"dd/mm/aaaa") -> Regiões 11, 12, 13, 22, 23 e 24 | 199 OSPs cadastradas | Atualizado em 30/09/2026
B5: INSERIR OSP → HISTÓRICO: | D5: Região 11 | F5: Região 12 | H5: Região 13 | J5: Região 22 | L5: Região 23 | N5: Região 24
B6: VER CONSOLIDADO → RESUMO: | D6: Região 11 | F6: Região 12 | H6: Região 13 | J6: Região 22 | L6: Região 23 | N6: Região 24
B7: próxima linha livre → | D7: ="linha "&(4+COUNTA('REGIÃO 11 - HISTÓRICO'!$C$4:$C$506)) -> linha 43 | F7: ="linha "&(4+COUNTA('REGIÃO 12 - HISTÓRICO'!$C$4:$C$497)) -> linha 57 | H7: ="linha "&(4+COUNTA('REGIÃO 13 - HISTÓRICO'!$C$4:$C$571)) -> linha 96 | J7: ="linha "&(4+COUNTA('REGIÃO 22 - HISTÓRICO'!$C$4:$C$507)) -> linha 12 | L7: ="linha "&(4+COUNTA('REGIÃO 23 - HISTÓRICO'!$C$4:$C$506)) -> linha 12 | N7: ="linha "&(4+COUNTA('REGIÃO 24 - HISTÓRICO'!$C$4:$C$509)) -> linha 10
C10: FILTRO — REGIÃO: | D10: REGIÃO 12
D12: N° DE OSPs | G12: VALOR PREVISTO (R$) | J12: TOTAL MEDIDO (R$) | M12: SALDO A MEDIR (R$)
D13: =COUNTIFS('BASE DASHBOARD'!$B$4:$B$217,'BASE DASHBOARD'!$Z$1) -> 53 | G13: =SUMIFS('BASE DASHBOARD'!$I$4:$I$217,'BASE DASHBOARD'!$B$4:$B$217,'BASE DASHBOARD'!$Z$1) -> 9892927 | J13: =SUMIFS('BASE DASHBOARD'!$J$4:$J$217,'BASE DASHBOARD'!$B$4:$B$217,'BASE DASHBOARD'!$Z$1) -> 8793229.6 | M13: =$G$13-$J$13 -> 1099697.4
D15: % DE EXECUÇÃO | G15: OSPs CONCLUÍDAS | J15: OSPs CANCELADAS | M15: VALOR MÉDIO / OSP (R$)
D16: =IFERROR($J$13/$G$13,0) -> 0.88884003 | G16: =COUNTIFS('BASE DASHBOARD'!$B$4:$B$217,'BASE DASHBOARD'!$Z$1,'BASE DASHBOARD'!$L$4:$L$217,"Concluída") -> 44 | J16: =COUNTIFS('BASE DASHBOARD'!$B$4:$B$217,'BASE DASHBOARD'!$Z$1,'BASE DASHBOARD'!$L$4:$L$217,"Cancelada") -> 0 | M16: =IFERROR($G$13/$D$13,0) -> 186659
M20: DETALHAMENTO
D25: FONTE: SISTEMA DE GESTÃO OSP - AGETO

Sheet DETALHAMENTO
B2: DETALHAMENTO OSPs — LOTE 04
B3: ="Regiões 11, 12, 13, 22, 23 e 24 | "&COUNTIF('BASE DASHBOARD'!$B$4:$B$217,"?*")&" OSPs cadastradas | Atualizado em "&TEXT(TODAY(),"dd/mm/aaaa") -> Regiões 11, 12, 13, 22, 23 e 24 | 199 OSPs cadastradas | Atualizado em 30/09/2026
C6: TOP 10 OSPs POR VALOR PREVISTO | J6: TOP 10 SERVIÇOS POR VALOR PREVISTO
C7: OSP | D7: # | E7: REGIÃO | F7: VALOR PREVISTO | G7: % DO TOTAL | J7: SERVIÇO | M7: # | N7: N° OSPs | O7: VALOR PREVISTO | P7: % DO TOTAL
C8: =IFERROR(INDEX('BASE DASHBOARD'!$AG$4:$AG$217,MATCH($D8,'BASE DASHBOARD'!$AJ$4:$AJ$217,0)),"") -> 009.2025.0102 | D8: =ROW()-7 -> 1 | E8: =IF($C8="","",IFERROR(INDEX('BASE DASHBOARD'!$AF$4:$AF$217,MATCH($D8,'BASE DASHBOARD'!$AJ$4:$AJ$217,0)),"")) -> R12 | F8: =IF($C8="","",IFERROR(INDEX('BASE DASHBOARD'!$AH$4:$AH$217,MATCH($D8,'BASE DASHBOARD'!$AJ$4:$AJ$217,0)),0)) -> 1847366.5 | G8: =IF($C8="","",IFERROR($F8/DASHBOARD!$G$13,0)) -> 0.18673609 | J8: =IFERROR(INDEX('BASE DASHBOARD'!$Z$4:$Z$217,MATCH($M8,'BASE DASHBOARD'!$AD$4:$AD$217,0)),"") -> Terraplenagem / Reconformação da plataforma / Recomposição do revestimento primário | M8: =ROW()-7 -> 1 | N8: =IF($J8="","",IFERROR(INDEX('BASE DASHBOARD'!$AA$4:$AA$217,MATCH($M8,'BASE DASHBOARD'!$AD$4:$AD$217,0)),0)) -> 11 | O8: =IF($J8="","",IFERROR(INDEX('BASE DASHBOARD'!$AB$4:$AB$217,MATCH($M8,'BASE DASHBOARD'!$AD$4:$AD$217,0)),0)) -> 6332107.5 | P8: =IF($J8="","",IFERROR($O8/DASHBOARD!$G$13,0)) -> 0.64006411
C9: =IFERROR(INDEX('BASE DASHBOARD'!$AG$4:$AG$217,MATCH($D9,'BASE DASHBOARD'!$AJ$4:$AJ$217,0)),"") -> 009.2025.0085 | D9: =ROW()-7 -> 2 | E9: =IF($C9="","",IFERROR(INDEX('BASE DASHBOARD'!$AF$4:$AF$217,MATCH($D9,'BASE DASHBOARD'!$AJ$4:$AJ$217,0)),"")) -> R12 | F9: =IF($C9="","",IFERROR(INDEX('BASE DASHBOARD'!$AH$4:$AH$217,MATCH($D9,'BASE DASHBOARD'!$AJ$4:$AJ$217,0)),0)) -> 1159513.6 | G9: =IF($C9="","",IFERROR($F9/DASHBOARD!$G$13,0)) -> 0.11720632 | J9: =IFERROR(INDEX('BASE DASHBOARD'!$Z$4:$Z$217,MATCH($M9,'BASE DASHBOARD'!$AD$4:$AD$217,0)),"") -> Roçada / Tapa-Buraco PMF / Remendo profundo | M9: =ROW()-7 -> 2 | N9: =IF($J9="","",IFERROR(INDEX('BASE DASHBOARD'!$AA$4:$AA$217,MATCH($M9,'BASE DASHBOARD'!$AD$4:$AD$217,0)),0)) -> 3 | O9: =IF($J9="","",IFERROR(INDEX('BASE DASHBOARD'!$AB$4:$AB$217,MATCH($M9,'BASE DASHBOARD'!$AD$4:$AD$217,0)),0)) -> 590002.77 | P9: =IF($J9="","",IFERROR($O9/DASHBOARD!$G$13,0)) -> 0.059638848
C10: =IFERROR(INDEX('BASE DASHBOARD'!$AG$4:$AG$217,MATCH($D10,'BASE DASHBOARD'!$AJ$4:$AJ$217,0)),"") -> 009.2025.0097 | D10: =ROW()-7 -> 3 | E10: =IF($C10="","",IFERROR(INDEX('BASE DASHBOARD'!$AF$4:$AF$217,MATCH($D10,'BASE DASHBOARD'!$AJ$4:$AJ$217,0)),"")) -> R12 | F10: =IF($C10="","",IFERROR(INDEX('BASE DASHBOARD'!$AH$4:$AH$217,MATCH($D10,'BASE DASHBOARD'!$AJ$4:$AJ$217,0)),0)) -> 674926.63 | G10: =IF($C10="","",IFERROR($F10/DASHBOARD!$G$13,0)) -> 0.068223149 | J10: =IFERROR(INDEX('BASE DASHBOARD'!$Z$4:$Z$217,MATCH($M10,'BASE DASHBOARD'!$AD$4:$AD$217,0)),"") -> Reconformação da plataforma | M10: =ROW()-7 -> 3 | N10: =IF($J10="","",IFERROR(INDEX('BASE DASHBOARD'!$AA$4:$AA$217,MATCH($M10,'BASE DASHBOARD'!$AD$4:$AD$217,0)),0)) -> 8 | O10: =IF($J10="","",IFERROR(INDEX('BASE DASHBOARD'!$AB$4:$AB$217,MATCH($M10,'BASE DASHBOARD'!$AD$4:$AD$217,0)),0)) -> 496783.32 | P10: =IF($J10="","",IFERROR($O10/DASHBOARD!$G$13,0)) -> 0.05021601
C11: =IFERROR(INDEX('BASE DASHBOARD'!$AG$4:$AG$217,MATCH($D11,'BASE DASHBOARD'!$AJ$4:$AJ$217,0)),"") -> 009.2025.0084 | D11: =ROW()-7 -> 4 | E11: =IF($C11="","",IFERROR(INDEX('BASE DASHBOARD'!$AF$4:$AF$217,MATCH($D11,'BASE DASHBOARD'!$AJ$4:$AJ$217,0)),"")) -> R12 | F11: =IF($C11="","",IFERROR(INDEX('BASE DASHBOARD'!$AH$4:$AH$217,MATCH($D11,'BASE DASHBOARD'!$AJ$4:$AJ$217,0)),0)) -> 664951.83 | G11: =IF($C11="","",IFERROR($F11/DASHBOARD!$G$13,0)) -> 0.067214873 | J11: =IFERROR(INDEX('BASE DASHBOARD'!$Z$4:$Z$217,MATCH($M11,'BASE DASHBOARD'!$AD$4:$AD$217,0)),"") -> Tapa-Buraco PMF | M11: =ROW()-7 -> 4 | N11: =IF($J11="","",IFERROR(INDEX('BASE DASHBOARD'!$AA$4:$AA$217,MATCH($M11,'BASE DASHBOARD'!$AD$4:$AD$217,0)),0)) -> 4 | O11: =IF($J11="","",IFERROR(INDEX('BASE DASHBOARD'!$AB$4:$AB$217,MATCH($M11,'BASE DASHBOARD'!$AD$4:$AD$217,0)),0)) -> 460405.57 | P11: =IF($J11="","",IFERROR($O11/DASHBOARD!$G$13,0)) -> 0.046538863
C12: =IFERROR(INDEX('BASE DASHBOARD'!$AG$4:$AG$217,MATCH($D12,'BASE DASHBOARD'!$AJ$4:$AJ$217,0)),"") -> 009.2025.0076 | D12: =ROW()-7 -> 5 | E12: =IF($C12="","",IFERROR(INDEX('BASE DASHBOARD'!$AF$4:$AF$217,MATCH($D12,'BASE DASHBOARD'!$AJ$4:$AJ$217,0)),"")) -> R12 | F12: =IF($C12="","",IFERROR(INDEX('BASE DASHBOARD'!$AH$4:$AH$217,MATCH($D12,'BASE DASHBOARD'!$AJ$4:$AJ$217,0)),0)) -> 615457.46 | G12: =IF($C12="","",IFERROR($F12/DASHBOARD!$G$13,0)) -> 0.062211867 | J12: =IFERROR(INDEX('BASE DASHBOARD'!$Z$4:$Z$217,MATCH($M12,'BASE DASHBOARD'!$AD$4:$AD$217,0)),"") -> Reconformação da plataforma / Recomposição do revestimento primário | M12: =ROW()-7 -> 5 | N12: =IF($J12="","",IFERROR(INDEX('BASE DASHBOARD'!$AA$4:$AA$217,MATCH($M12,'BASE DASHBOARD'!$AD$4:$AD$217,0)),0)) -> 1 | O12: =IF($J12="","",IFERROR(INDEX('BASE DASHBOARD'!$AB$4:$AB$217,MATCH($M12,'BASE DASHBOARD'!$AD$4:$AD$217,0)),0)) -> 364826.92 | P12: =IF($J12="","",IFERROR($O12/DASHBOARD!$G$13,0)) -> 0.036877551
C13: =IFERROR(INDEX('BASE DASHBOARD'!$AG$4:$AG$217,MATCH($D13,'BASE DASHBOARD'!$AJ$4:$AJ$217,0)),"") -> 009.2025.0083 | D13: =ROW()-7 -> 6 | E13: =IF($C13="","",IFERROR(INDEX('BASE DASHBOARD'!$AF$4:$AF$217,MATCH($D13,'BASE DASHBOARD'!$AJ$4:$AJ$217,0)),"")) -> R12 | F13: =IF($C13="","",IFERROR(INDEX('BASE DASHBOARD'!$AH$4:$AH$217,MATCH($D13,'BASE DASHBOARD'!$AJ$4:$AJ$217,0)),0)) -> 461352.19 | G13: =IF($C13="","",IFERROR($F13/DASHBOARD!$G$13,0)) -> 0.046634549 | J13: =IFERROR(INDEX('BASE DASHBOARD'!$Z$4:$Z$217,MATCH($M13,'BASE DASHBOARD'!$AD$4:$AD$217,0)),"") -> Tapa-Buraco CAE | M13: =ROW()-7 -> 6 | N13: =IF($J13="","",IFERROR(INDEX('BASE DASHBOARD'!$AA$4:$AA$217,MATCH($M13,'BASE DASHBOARD'!$AD$4:$AD$217,0)),0)) -> 3 | O13: =IF($J13="","",IFERROR(INDEX('BASE DASHBOARD'!$AB$4:$AB$217,MATCH($M13,'BASE DASHBOARD'!$AD$4:$AD$217,0)),0)) -> 343391.27 | P13: =IF($J13="","",IFERROR($O13/DASHBOARD!$G$13,0)) -> 0.034710786
C14: =IFERROR(INDEX('BASE DASHBOARD'!$AG$4:$AG$217,MATCH($D14,'BASE DASHBOARD'!$AJ$4:$AJ$217,0)),"") -> 009.2025.0086 | D14: =ROW()-7 -> 7 | E14: =IF($C14="","",IFERROR(INDEX('BASE DASHBOARD'!$AF$4:$AF$217,MATCH($D14,'BASE DASHBOARD'!$AJ$4:$AJ$217,0)),"")) -> R12 | F14: =IF($C14="","",IFERROR(INDEX('BASE DASHBOARD'!$AH$4:$AH$217,MATCH($D14,'BASE DASHBOARD'!$AJ$4:$AJ$217,0)),0)) -> 435739.41 | G14: =IF($C14="","",IFERROR($F14/DASHBOARD!$G$13,0)) -> 0.04404555 | J14: =IFERROR(INDEX('BASE DASHBOARD'!$Z$4:$Z$217,MATCH($M14,'BASE DASHBOARD'!$AD$4:$AD$217,0)),"") -> Tapa-Buraco CAE / Remendo Profundo | M14: =ROW()-7 -> 7 | N14: =IF($J14="","",IFERROR(INDEX('BASE DASHBOARD'!$AA$4:$AA$217,MATCH($M14,'BASE DASHBOARD'!$AD$4:$AD$217,0)),0)) -> 2 | O14: =IF($J14="","",IFERROR(INDEX('BASE DASHBOARD'!$AB$4:$AB$217,MATCH($M14,'BASE DASHBOARD'!$AD$4:$AD$217,0)),0)) -> 322053.46 | P14: =IF($J14="","",IFERROR($O14/DASHBOARD!$G$13,0)) -> 0.03255391
C15: =IFERROR(INDEX('BASE DASHBOARD'!$AG$4:$AG$217,MATCH($D15,'BASE DASHBOARD'!$AJ$4:$AJ$217,0)),"") -> 009.2025.0068 | D15: =ROW()-7 -> 8 | E15: =IF($C15="","",IFERROR(INDEX('BASE DASHBOARD'!$AF$4:$AF$217,MATCH($D15,'BASE DASHBOARD'!$AJ$4:$AJ$217,0)),"")) -> R12 | F15: =IF($C15="","",IFERROR(INDEX('BASE DASHBOARD'!$AH$4:$AH$217,MATCH($D15,'BASE DASHBOARD'!$AJ$4:$AJ$217,0)),0)) -> 364826.92 | G15: =IF($C15="","",IFERROR($F15/DASHBOARD!$G$13,0)) -> 0.036877551 | J15: =IFERROR(INDEX('BASE DASHBOARD'!$Z$4:$Z$217,MATCH($M15,'BASE DASHBOARD'!$AD$4:$AD$217,0)),"") -> Roçada / Tapa-Buraco CAE / Remendo Profundo | M15: =ROW()-7 -> 8 | N15: =IF($J15="","",IFERROR(INDEX('BASE DASHBOARD'!$AA$4:$AA$217,MATCH($M15,'BASE DASHBOARD'!$AD$4:$AD$217,0)),0)) -> 3 | O15: =IF($J15="","",IFERROR(INDEX('BASE DASHBOARD'!$AB$4:$AB$217,MATCH($M15,'BASE DASHBOARD'!$AD$4:$AD$217,0)),0)) -> 315965.76 | P15: =IF($J15="","",IFERROR($O15/DASHBOARD!$G$13,0)) -> 0.031938552
C16: =IFERROR(INDEX('BASE DASHBOARD'!$AG$4:$AG$217,MATCH($D16,'BASE DASHBOARD'!$AJ$4:$AJ$217,0)),"") -> 009.2025.0075 | D16: =ROW()-7 -> 9 | E16: =IF($C16="","",IFERROR(INDEX('BASE DASHBOARD'!$AF$4:$AF$217,MATCH($D16,'BASE DASHBOARD'!$AJ$4:$AJ$217,0)),"")) -> R12 | F16: =IF($C16="","",IFERROR(INDEX('BASE DASHBOARD'!$AH$4:$AH$217,MATCH($D16,'BASE DASHBOARD'!$AJ$4:$AJ$217,0)),0)) -> 295343.5 | G16: =IF($C16="","",IFERROR($F16/DASHBOARD!$G$13,0)) -> 0.029854006 | J16: =IFERROR(INDEX('BASE DASHBOARD'!$Z$4:$Z$217,MATCH($M16,'BASE DASHBOARD'!$AD$4:$AD$217,0)),"") -> Roçada | M16: =ROW()-7 -> 9 | N16: =IF($J16="","",IFERROR(INDEX('BASE DASHBOARD'!$AA$4:$AA$217,MATCH($M16,'BASE DASHBOARD'!$AD$4:$AD$217,0)),0)) -> 11 | O16: =IF($J16="","",IFERROR(INDEX('BASE DASHBOARD'!$AB$4:$AB$217,MATCH($M16,'BASE DASHBOARD'!$AD$4:$AD$217,0)),0)) -> 208416.53 | P16: =IF($J16="","",IFERROR($O16/DASHBOARD!$G$13,0)) -> 0.021067226
C17: =IFERROR(INDEX('BASE DASHBOARD'!$AG$4:$AG$217,MATCH($D17,'BASE DASHBOARD'!$AJ$4:$AJ$217,0)),"") -> 009.2025.0081 | D17: =ROW()-7 -> 10 | E17: =IF($C17="","",IFERROR(INDEX('BASE DASHBOARD'!$AF$4:$AF$217,MATCH($D17,'BASE DASHBOARD'!$AJ$4:$AJ$217,0)),"")) -> R12 | F17: =IF($C17="","",IFERROR(INDEX('BASE DASHBOARD'!$AH$4:$AH$217,MATCH($D17,'BASE DASHBOARD'!$AJ$4:$AJ$217,0)),0)) -> 284302.32 | G17: =IF($C17="","",IFERROR($F17/DASHBOARD!$G$13,0)) -> 0.028737938 | J17: =IFERROR(INDEX('BASE DASHBOARD'!$Z$4:$Z$217,MATCH($M17,'BASE DASHBOARD'!$AD$4:$AD$217,0)),"") -> Roçada / Caiação de EDS e pontes | M17: =ROW()-7 -> 10 | N17: =IF($J17="","",IFERROR(INDEX('BASE DASHBOARD'!$AA$4:$AA$217,MATCH($M17,'BASE DASHBOARD'!$AD$4:$AD$217,0)),0)) -> 4 | O17: =IF($J17="","",IFERROR(INDEX('BASE DASHBOARD'!$AB$4:$AB$217,MATCH($M17,'BASE DASHBOARD'!$AD$4:$AD$217,0)),0)) -> 208338.05 | P17: =IF($J17="","",IFERROR($O17/DASHBOARD!$G$13,0)) -> 0.021059293
C24: COMPARATIVO POR REGIÃO
C25: REGIÃO | D25: CONTRATO | E25: N° OSPs | F25: CONCLUÍDAS | G25: CANCELADAS | H25: VALOR PREVISTO | I25: TOTAL MEDIDO | J25: SALDO | K25: % EXEC.
C26: ='Tabelas Auxiliares'!B4 -> R11 | D26: ='Tabelas Auxiliares'!E4 -> 049.2024 | E26: =COUNTIFS('BASE DASHBOARD'!$B$4:$B$217,$C26) -> 39 | F26: =COUNTIFS('BASE DASHBOARD'!$B$4:$B$217,$C26,'BASE DASHBOARD'!$L$4:$L$217,"Concluída") -> 23 | G26: =COUNTIFS('BASE DASHBOARD'!$B$4:$B$217,$C26,'BASE DASHBOARD'!$L$4:$L$217,"Cancelada") -> 4 | H26: =SUMIFS('BASE DASHBOARD'!$I$4:$I$217,'BASE DASHBOARD'!$B$4:$B$217,$C26) -> 4157179.7 | I26: =SUMIFS('BASE DASHBOARD'!$J$4:$J$217,'BASE DASHBOARD'!$B$4:$B$217,$C26) -> 2632614.4 | J26: =H26-I26 -> 1524565.2 | K26: =IFERROR(I26/H26,0) -> 0.63326934
C27: ='Tabelas Auxiliares'!B5 -> R12 | D27: ='Tabelas Auxiliares'!E5 -> 009.2025 | E27: =COUNTIFS('BASE DASHBOARD'!$B$4:$B$217,$C27) -> 53 | F27: =COUNTIFS('BASE DASHBOARD'!$B$4:$B$217,$C27,'BASE DASHBOARD'!$L$4:$L$217,"Concluída") -> 44 | G27: =COUNTIFS('BASE DASHBOARD'!$B$4:$B$217,$C27,'BASE DASHBOARD'!$L$4:$L$217,"Cancelada") -> 0 | H27: =SUMIFS('BASE DASHBOARD'!$I$4:$I$217,'BASE DASHBOARD'!$B$4:$B$217,$C27) -> 9892927 | I27: =SUMIFS('BASE DASHBOARD'!$J$4:$J$217,'BASE DASHBOARD'!$B$4:$B$217,$C27) -> 8793229.6 | J27: =H27-I27 -> 1099697.4 | K27: =IFERROR(I27/H27,0) -> 0.88884003
C28: ='Tabelas Auxiliares'!B6 -> R13 | D28: ='Tabelas Auxiliares'!E6 -> 051.2024 | E28: =COUNTIFS('BASE DASHBOARD'!$B$4:$B$217,$C28) -> 92 | F28: =COUNTIFS('BASE DASHBOARD'!$B$4:$B$217,$C28,'BASE DASHBOARD'!$L$4:$L$217,"Concluída") -> 64 | G28: =COUNTIFS('BASE DASHBOARD'!$B$4:$B$217,$C28,'BASE DASHBOARD'!$L$4:$L$217,"Cancelada") -> 0 | H28: =SUMIFS('BASE DASHBOARD'!$I$4:$I$217,'BASE DASHBOARD'!$B$4:$B$217,$C28) -> 16489091 | I28: =SUMIFS('BASE DASHBOARD'!$J$4:$J$217,'BASE DASHBOARD'!$B$4:$B$217,$C28) -> 13456411 | J28: =H28-I28 -> 3032679.4 | K28: =IFERROR(I28/H28,0) -> 0.81607965
C29: ='Tabelas Auxiliares'!B7 -> R22 | D29: ='Tabelas Auxiliares'!E7 -> 042.2025 | E29: =COUNTIFS('BASE DASHBOARD'!$B$4:$B$217,$C29) -> 7 | F29: =COUNTIFS('BASE DASHBOARD'!$B$4:$B$217,$C29,'BASE DASHBOARD'!$L$4:$L$217,"Concluída") -> 2 | G29: =COUNTIFS('BASE DASHBOARD'!$B$4:$B$217,$C29,'BASE DASHBOARD'!$L$4:$L$217,"Cancelada") -> 0 | H29: =SUMIFS('BASE DASHBOARD'!$I$4:$I$217,'BASE DASHBOARD'!$B$4:$B$217,$C29) -> 39969136 | I29: =SUMIFS('BASE DASHBOARD'!$J$4:$J$217,'BASE DASHBOARD'!$B$4:$B$217,$C29) -> 17891793 | J29: =H29-I29 -> 22077343 | K29: =IFERROR(I29/H29,0) -> 0.44764023
C30: ='Tabelas Auxiliares'!B8 -> R23 | D30: ='Tabelas Auxiliares'!E8 -> 043.2025 | E30: =COUNTIFS('BASE DASHBOARD'!$B$4:$B$217,$C30) -> 2 | F30: =COUNTIFS('BASE DASHBOARD'!$B$4:$B$217,$C30,'BASE DASHBOARD'!$L$4:$L$217,"Concluída") -> 0 | G30: =COUNTIFS('BASE DASHBOARD'!$B$4:$B$217,$C30,'BASE DASHBOARD'!$L$4:$L$217,"Cancelada") -> 0 | H30: =SUMIFS('BASE DASHBOARD'!$I$4:$I$217,'BASE DASHBOARD'!$B$4:$B$217,$C30) -> 0 | I30: =SUMIFS('BASE DASHBOARD'!$J$4:$J$217,'BASE DASHBOARD'!$B$4:$B$217,$C30) -> 0 | J30: =H30-I30 -> 0 | K30: =IFERROR(I30/H30,0) -> 0
C31: ='Tabelas Auxiliares'!B9 -> R24 | D31: ='Tabelas Auxiliares'!E9 -> 041.2025 | E31: =COUNTIFS('BASE DASHBOARD'!$B$4:$B$217,$C31) -> 6 | F31: =COUNTIFS('BASE DASHBOARD'!$B$4:$B$217,$C31,'BASE DASHBOARD'!$L$4:$L$217,"Concluída") -> 4 | G31: =COUNTIFS('BASE DASHBOARD'!$B$4:$B$217,$C31,'BASE DASHBOARD'!$L$4:$L$217,"Cancelada") -> 0 | H31: =SUMIFS('BASE DASHBOARD'!$I$4:$I$217,'BASE DASHBOARD'!$B$4:$B$217,$C31) -> 15211656 | I31: =SUMIFS('BASE DASHBOARD'!$J$4:$J$217,'BASE DASHBOARD'!$B$4:$B$217,$C31) -> 12628850 | J31: =H31-I31 -> 2582806.3 | K31: =IFERROR(I31/H31,0) -> 0.83020873
C32: TOTAL — LOTE 04 | E32: =SUM(E26:E31) -> 199 | F32: =SUM(F26:F31) -> 137 | G32: =SUM(G26:G31) -> 4 | H32: =SUM(H26:H31) -> 85719990 | I32: =SUM(I26:I31) -> 55402899 | J32: =SUM(J26:J31) -> 30317091 | K32: =IFERROR(I32/H32,0) -> 0.64632414
C39: SITUAÇÃO DAS OSPs
C40: SITUAÇÃO | D40: N° OSPs | E40: % DAS OSPs | F40: VALOR PREVISTO | G40: TOTAL MEDIDO | H40: % DO VALOR
C41: ='Tabelas Auxiliares'!M4 -> Em elaboração | D41: =COUNTIFS('BASE DASHBOARD'!$L$4:$L$217,$C41,'BASE DASHBOARD'!$B$4:$B$217,'BASE DASHBOARD'!$Z$1) -> 7 | E41: =IFERROR(D41/$D$46,0) -> 0.13461538 | F41: =SUMIFS('BASE DASHBOARD'!$I$4:$I$217,'BASE DASHBOARD'!$L$4:$L$217,$C41,'BASE DASHBOARD'!$B$4:$B$217,'BASE DASHBOARD'!$Z$1) -> 372403.12 | G41: =SUMIFS('BASE DASHBOARD'!$J$4:$J$217,'BASE DASHBOARD'!$L$4:$L$217,$C41,'BASE DASHBOARD'!$B$4:$B$217,'BASE DASHBOARD'!$Z$1) -> 0 | H41: =IFERROR(F41/$F$46,0) -> 0.037643371
C42: ='Tabelas Auxiliares'!M5 -> Em andamento | D42: =COUNTIFS('BASE DASHBOARD'!$L$4:$L$217,$C42,'BASE DASHBOARD'!$B$4:$B$217,'BASE DASHBOARD'!$Z$1) -> 1 | E42: =IFERROR(D42/$D$46,0) -> 0.019230769 | F42: =SUMIFS('BASE DASHBOARD'!$I$4:$I$217,'BASE DASHBOARD'!$L$4:$L$217,$C42,'BASE DASHBOARD'!$B$4:$B$217,'BASE DASHBOARD'!$Z$1) -> 69999.89 | G42: =SUMIFS('BASE DASHBOARD'!$J$4:$J$217,'BASE DASHBOARD'!$L$4:$L$217,$C42,'BASE DASHBOARD'!$B$4:$B$217,'BASE DASHBOARD'!$Z$1) -> 68354.64 | H42: =IFERROR(F42/$F$46,0) -> 0.0070757512
C43: ='Tabelas Auxiliares'!M6 -> Concluída | D43: =COUNTIFS('BASE DASHBOARD'!$L$4:$L$217,$C43,'BASE DASHBOARD'!$B$4:$B$217,'BASE DASHBOARD'!$Z$1) -> 44 | E43: =IFERROR(D43/$D$46,0) -> 0.84615385 | F43: =SUMIFS('BASE DASHBOARD'!$I$4:$I$217,'BASE DASHBOARD'!$L$4:$L$217,$C43,'BASE DASHBOARD'!$B$4:$B$217,'BASE DASHBOARD'!$Z$1) -> 9450524 | G43: =SUMIFS('BASE DASHBOARD'!$J$4:$J$217,'BASE DASHBOARD'!$L$4:$L$217,$C43,'BASE DASHBOARD'!$B$4:$B$217,'BASE DASHBOARD'!$Z$1) -> 8724874.9 | H43: =IFERROR(F43/$F$46,0) -> 0.95528088
C44: ='Tabelas Auxiliares'!M7 -> Justificada | D44: =COUNTIFS('BASE DASHBOARD'!$L$4:$L$217,$C44,'BASE DASHBOARD'!$B$4:$B$217,'BASE DASHBOARD'!$Z$1) -> 0 | E44: =IFERROR(D44/$D$46,0) -> 0 | F44: =SUMIFS('BASE DASHBOARD'!$I$4:$I$217,'BASE DASHBOARD'!$L$4:$L$217,$C44,'BASE DASHBOARD'!$B$4:$B$217,'BASE DASHBOARD'!$Z$1) -> 0 | G44: =SUMIFS('BASE DASHBOARD'!$J$4:$J$217,'BASE DASHBOARD'!$L$4:$L$217,$C44,'BASE DASHBOARD'!$B$4:$B$217,'BASE DASHBOARD'!$Z$1) -> 0 | H44: =IFERROR(F44/$F$46,0) -> 0
C45: ='Tabelas Auxiliares'!M8 -> Cancelada | D45: =COUNTIFS('BASE DASHBOARD'!$L$4:$L$217,$C45,'BASE DASHBOARD'!$B$4:$B$217,'BASE DASHBOARD'!$Z$1) -> 0 | E45: =IFERROR(D45/$D$46,0) -> 0 | F45: =SUMIFS('BASE DASHBOARD'!$I$4:$I$217,'BASE DASHBOARD'!$L$4:$L$217,$C45,'BASE DASHBOARD'!$B$4:$B$217,'BASE DASHBOARD'!$Z$1) -> 0 | G45: =SUMIFS('BASE DASHBOARD'!$J$4:$J$217,'BASE DASHBOARD'!$L$4:$L$217,$C45,'BASE DASHBOARD'!$B$4:$B$217,'BASE DASHBOARD'!$Z$1) -> 0 | H45: =IFERROR(F45/$F$46,0) -> 0
C46: TOTAL | D46: =SUM(D41:D45) -> 52 | E46: =SUM(E41:E45) -> 1 | F46: =SUM(F41:F45) -> 9892927 | G46: =SUM(G41:G45) -> 8793229.6 | H46: =SUM(H41:H45) -> 1
C53: EVOLUÇÃO MENSAL — 2026
C54: MÊS | D54: ='BASE DASHBOARD'!M$3 -> 46023 | E54: ='BASE DASHBOARD'!N$3 -> 46054 | F54: ='BASE DASHBOARD'!O$3 -> 46082 | G54: ='BASE DASHBOARD'!P$3 -> 46113 | H54: ='BASE DASHBOARD'!Q$3 -> 46143 | I54: ='BASE DASHBOARD'!R$3 -> 46174 | J54: ='BASE DASHBOARD'!S$3 -> 46204 | K54: ='BASE DASHBOARD'!T$3 -> 46235 | ... O54: ='BASE DASHBOARD'!X$3 -> 46357
C55: Valor medido no mês | D55: =SUMIFS('BASE DASHBOARD'!M$4:M$217,'BASE DASHBOARD'!$B$4:$B$217,'BASE DASHBOARD'!$Z$1) -> 392381.67 | E55: =SUMIFS('BASE DASHBOARD'!N$4:N$217,'BASE DASHBOARD'!$B$4:$B$217,'BASE DASHBOARD'!$Z$1) -> 1299128.3 | F55: =SUMIFS('BASE DASHBOARD'!O$4:O$217,'BASE DASHBOARD'!$B$4:$B$217,'BASE DASHBOARD'!$Z$1) -> 178577.47 | G55: =SUMIFS('BASE DASHBOARD'!P$4:P$217,'BASE DASHBOARD'!$B$4:$B$217,'BASE DASHBOARD'!$Z$1) -> 1343283.7 | H55: =SUMIFS('BASE DASHBOARD'!Q$4:Q$217,'BASE DASHBOARD'!$B$4:$B$217,'BASE DASHBOARD'!$Z$1) -> 1563240 | I55: =SUMIFS('BASE DASHBOARD'!R$4:R$217,'BASE DASHBOARD'!$B$4:$B$217,'BASE DASHBOARD'!$Z$1) -> 1283773.5 | J55: =SUMIFS('BASE DASHBOARD'!S$4:S$217,'BASE DASHBOARD'!$B$4:$B$217,'BASE DASHBOARD'!$Z$1) -> 2159251.1 | K55: =SUMIFS('BASE DASHBOARD'!T$4:T$217,'BASE DASHBOARD'!$B$4:$B$217,'BASE DASHBOARD'!$Z$1) -> 573593.78 | ... O55: =SUMIFS('BASE DASHBOARD'!X$4:X$217,'BASE DASHBOARD'!$B$4:$B$217,'BASE DASHBOARD'!$Z$1) -> 0
C56: Acumulado | D56: =D55 -> 392381.67 | E56: =D56+E55 -> 1691510 | F56: =E56+F55 -> 1870087.4 | G56: =F56+G55 -> 3213371.2 | H56: =G56+H55 -> 4776611.2 | I56: =H56+I55 -> 6060384.7 | J56: =I56+J55 -> 8219635.8 | K56: =J56+K55 -> 8793229.6 | L56: =K56+L55 -> 8793229.6 | ... O56: =N56+O55 -> 8793229.6
C57: % do valor previsto | D57: =IFERROR(D56/DASHBOARD!$G$13,0) -> 0.039662849 | E57: =IFERROR(E56/DASHBOARD!$G$13,0) -> 0.17098175 | F57: =IFERROR(F56/DASHBOARD!$G$13,0) -> 0.18903277 | G57: =IFERROR(G56/DASHBOARD!$G$13,0) -> 0.32481501 | H57: =IFERROR(H56/DASHBOARD!$G$13,0) -> 0.48283094 | I57: =IFERROR(I56/DASHBOARD!$G$13,0) -> 0.61259774 | J57: =IFERROR(J56/DASHBOARD!$G$13,0) -> 0.83085984 | K57: =IFERROR(K56/DASHBOARD!$G$13,0) -> 0.88884003 | ... O57: =IFERROR(O56/DASHBOARD!$G$13,0) -> 0.88884003
C58: OSPs com medição | D58: =COUNTIFS('BASE DASHBOARD'!$B$4:$B$217,'BASE DASHBOARD'!$Z$1,'BASE DASHBOARD'!M$4:M$217,">0") -> 2 | E58: =COUNTIFS('BASE DASHBOARD'!$B$4:$B$217,'BASE DASHBOARD'!$Z$1,'BASE DASHBOARD'!N$4:N$217,">0") -> 10 | F58: =COUNTIFS('BASE DASHBOARD'!$B$4:$B$217,'BASE DASHBOARD'!$Z$1,'BASE DASHBOARD'!O$4:O$217,">0") -> 3 | G58: =COUNTIFS('BASE DASHBOARD'!$B$4:$B$217,'BASE DASHBOARD'!$Z$1,'BASE DASHBOARD'!P$4:P$217,">0") -> 7 | H58: =COUNTIFS('BASE DASHBOARD'!$B$4:$B$217,'BASE DASHBOARD'!$Z$1,'BASE DASHBOARD'!Q$4:Q$217,">0") -> 3 | I58: =COUNTIFS('BASE DASHBOARD'!$B$4:$B$217,'BASE DASHBOARD'!$Z$1,'BASE DASHBOARD'!R$4:R$217,">0") -> 9 | J58: =COUNTIFS('BASE DASHBOARD'!$B$4:$B$217,'BASE DASHBOARD'!$Z$1,'BASE DASHBOARD'!S$4:S$217,">0") -> 9 | K58: =COUNTIFS('BASE DASHBOARD'!$B$4:$B$217,'BASE DASHBOARD'!$Z$1,'BASE DASHBOARD'!T$4:T$217,">0") -> 14 | ... O58: =COUNTIFS('BASE DASHBOARD'!$B$4:$B$217,'BASE DASHBOARD'!$Z$1,'BASE DASHBOARD'!X$4:X$217,">0") -> 0
C62: FONTE: SISTEMA DE GESTÃO OSP - AGETO
R70: DADOS DOS GRÁFICOS (apoio)
R71: REGIÃO | S71: Valor Previsto | T71: Total Medido | V71: REGIÃO | W71: N° OSPs
...

Sheet REGIÃO 11 - RESUMO
B2: REGIÃO 11
B3: ID | C3: REGIÃO | D3: CONTRATO | E3: OSP | F3: DATA EMISSÃO | G3: CRONOGRAMA | H3: N° TRECHO | I3: TRECHO | J3: SERVIÇO | K3: VALOR PREVISTO | L3: SITUAÇÃO | M3: OBSERVAÇÃO
B4: ='REGIÃO 11 - HISTÓRICO'!B4 -> 1 | C4: R11 | D4: =_xlfn.XLOOKUP(tbResumoR11[[#This Row],[REGIÃO]],tbRegioes[Código Região],tbRegioes[Contrato],"") -> 049.2024 | E4: ='REGIÃO 11 - HISTÓRICO'!C4 -> 14 | F4: Janeiro | G4: ='REGIÃO 11 - HISTÓRICO'!D4 -> jan/fev/mar | H4: 204 | I4: =IF(tbResumoR11[[#This Row],[N° TRECHO]]="","",IFERROR(INDEX('REGIÃO 11 - TRECHOS'!$F$4:$F$119,MATCH(tbResumoR11[[#This Row],[N° TRECHO]],'REGIÃO 11 - TRECHOS'!$E$4:$E$119,0)),IFERROR(INDEX('REGIÃO 12 - TRECHOS'!$F$4:$F$76,MATCH(tbResumoR11[[#This Row],[N° TRECHO]],'REGIÃO 12 - TRECHOS'!$E$4:$E$76,0)),IFERROR(INDEX('REGIÃO 13 - TRECHOS'!$F$4:$F$53,MATCH(tbResumoR11[[#This Row],[N° TRECHO]],'REGIÃO 13 - TRECHOS'!$E$4:$E$53,0)),"Trecho não cadastrado")))) -> RODOVIA TO-070 - TRECHO ALIANÇA DO TOCANTINS - BREJINHO DE NAZARÉ | J4: Roçada / Tapa-Buraco CAE | K4: ='REGIÃO 11 - HISTÓRICO'!E4 -> 177657.57 | L4: ='REGIÃO 11 - HISTÓRICO'!I4 -> Concluída
B5: ='REGIÃO 11 - HISTÓRICO'!B5 -> 2 | C5: R11 | D5: =_xlfn.XLOOKUP(tbResumoR11[[#This Row],[REGIÃO]],tbRegioes[Código Região],tbRegioes[Contrato],"") -> 049.2024 | E5: ='REGIÃO 11 - HISTÓRICO'!C5 -> 15 | F5: Janeiro | G5: ='REGIÃO 11 - HISTÓRICO'!D5 -> jan/fev | H5: 212 | I5: =IF(tbResumoR11[[#This Row],[N° TRECHO]]="","",IFERROR(INDEX('REGIÃO 11 - TRECHOS'!$F$4:$F$119,MATCH(tbResumoR11[[#This Row],[N° TRECHO]],'REGIÃO 11 - TRECHOS'!$E$4:$E$119,0)),IFERROR(INDEX('REGIÃO 12 - TRECHOS'!$F$4:$F$76,MATCH(tbResumoR11[[#This Row],[N° TRECHO]],'REGIÃO 12 - TRECHOS'!$E$4:$E$76,0)),IFERROR(INDEX('REGIÃO 13 - TRECHOS'!$F$4:$F$53,MATCH(tbResumoR11[[#This Row],[N° TRECHO]],'REGIÃO 13 - TRECHOS'!$E$4:$E$53,0)),"Trecho não cadastrado")))) -> RODOVIA TO-181 - TRECHO ARAGUAÇU - SANDOLÂNDIA | J5: Roçada | K5: ='REGIÃO 11 - HISTÓRICO'!E5 -> 25453.98 | L5: ='REGIÃO 11 - HISTÓRICO'!I5 -> Concluída
B6: ='REGIÃO 11 - HISTÓRICO'!B6 -> 3 | C6: R11 | D6: =_xlfn.XLOOKUP(tbResumoR11[[#This Row],[REGIÃO]],tbRegioes[Código Região],tbRegioes[Contrato],"") -> 049.2024 | E6: ='REGIÃO 11 - HISTÓRICO'!C6 -> 16 | F6: Janeiro | G6: ='REGIÃO 11 - HISTÓRICO'!D6 -> jan/fev/mar | H6: 220 | I6: =IF(tbResumoR11[[#This Row],[N° TRECHO]]="","",IFERROR(INDEX('REGIÃO 11 - TRECHOS'!$F$4:$F$119,MATCH(tbResumoR11[[#This Row],[N° TRECHO]],'REGIÃO 11 - TRECHOS'!$E$4:$E$119,0)),IFERROR(INDEX('REGIÃO 12 - TRECHOS'!$F$4:$F$76,MATCH(tbResumoR11[[#This Row],[N° TRECHO]],'REGIÃO 12 - TRECHOS'!$E$4:$E$76,0)),IFERROR(INDEX('REGIÃO 13 - TRECHOS'!$F$4:$F$53,MATCH(tbResumoR11[[#This Row],[N° TRECHO]],'REGIÃO 13 - TRECHOS'!$E$4:$E$53,0)),"Trecho não cadastrado")))) -> RODOVIA TO-460 - TRECHO BR-242 (VILA QUIXABA) - SUCUPIRA | J6: Roçada / Tapa-Buraco CAE | K6: ='REGIÃO 11 - HISTÓRICO'!E6 -> 42260.27 | L6: ='REGIÃO 11 - HISTÓRICO'!I6 -> Concluída
B7: ='REGIÃO 11 - HISTÓRICO'!B7 -> 4 | C7: R11 | D7: =_xlfn.XLOOKUP(tbResumoR11[[#This Row],[REGIÃO]],tbRegioes[Código Região],tbRegioes[Contrato],"") -> 049.2024 | E7: ='REGIÃO 11 - HISTÓRICO'!C7 -> 17 | F7: Janeiro | G7: ='REGIÃO 11 - HISTÓRICO'!D7 -> jan/fev | H7: 218 | I7: =IF(tbResumoR11[[#This Row],[N° TRECHO]]="","",IFERROR(INDEX('REGIÃO 11 - TRECHOS'!$F$4:$F$119,MATCH(tbResumoR11[[#This Row],[N° TRECHO]],'REGIÃO 11 - TRECHOS'!$E$4:$E$119,0)),IFERROR(INDEX('REGIÃO 12 - TRECHOS'!$F$4:$F$76,MATCH(tbResumoR11[[#This Row],[N° TRECHO]],'REGIÃO 12 - TRECHOS'!$E$4:$E$76,0)),IFERROR(INDEX('REGIÃO 13 - TRECHOS'!$F$4:$F$53,MATCH(tbResumoR11[[#This Row],[N° TRECHO]],'REGIÃO 13 - TRECHOS'!$E$4:$E$53,0)),"Trecho não cadastrado")))) -> RODOVIA TO-373 - TRECHO ALVORADA - ARAGUAÇU - DIVISA TO-GO | J7: Roçada | K7: ='REGIÃO 11 - HISTÓRICO'!E7 -> 50319.98 | L7: ='REGIÃO 11 - HISTÓRICO'!I7 -> Concluída
B8: ='REGIÃO 11 - HISTÓRICO'!B8 -> 5 | C8: R11 | D8: =_xlfn.XLOOKUP(tbResumoR11[[#This Row],[REGIÃO]],tbRegioes[Código Região],tbRegioes[Contrato],"") -> 049.2024 | E8: ='REGIÃO 11 - HISTÓRICO'!C8 -> 18 | F8: Fevereiro | G8: ='REGIÃO 11 - HISTÓRICO'!D8 -> fev/mar/abr | H8: 208 | I8: =IF(tbResumoR11[[#This Row],[N° TRECHO]]="","",IFERROR(INDEX('REGIÃO 11 - TRECHOS'!$F$4:$F$119,MATCH(tbResumoR11[[#This Row],[N° TRECHO]],'REGIÃO 11 - TRECHOS'!$E$4:$E$119,0)),IFERROR(INDEX('REGIÃO 12 - TRECHOS'!$F$4:$F$76,MATCH(tbResumoR11[[#This Row],[N° TRECHO]],'REGIÃO 12 - TRECHOS'!$E$4:$E$76,0)),IFERROR(INDEX('REGIÃO 13 - TRECHOS'!$F$4:$F$53,MATCH(tbResumoR11[[#This Row],[N° TRECHO]],'REGIÃO 13 - TRECHOS'!$E$4:$E$53,0)),"Trecho não cadastrado")))) -> RODOVIA TO-181 - TRECHO ENTR. TO-481 (CAPAO DO COCO) - FAZENDA COBRAPE | J8: Reconformação da plataforma / Recomposição do revestimento primário | K8: ='REGIÃO 11 - HISTÓRICO'!E8 -> 842266.55 | L8: ='REGIÃO 11 - HISTÓRICO'!I8 -> Concluída
B9: ='REGIÃO 11 - HISTÓRICO'!B9 -> 6 | C9: R11 | D9: =_xlfn.XLOOKUP(tbResumoR11[[#This Row],[REGIÃO]],tbRegioes[Código Região],tbRegioes[Contrato],"") -> 049.2024 | E9: ='REGIÃO 11 - HISTÓRICO'!C9 -> 19 | F9: Fevereiro | G9: ='REGIÃO 11 - HISTÓRICO'!D9 -> fev/mar/abr | H9: 221 | I9: =IF(tbResumoR11[[#This Row],[N° TRECHO]]="","",IFERROR(INDEX('REGIÃO 11 - TRECHOS'!$F$4:$F$119,MATCH(tbResumoR11[[#This Row],[N° TRECHO]],'REGIÃO 11 - TRECHOS'!$E$4:$E$119,0)),IFERROR(INDEX('REGIÃO 12 - TRECHOS'!$F$4:$F$76,MATCH(tbResumoR11[[#This Row],[N° TRECHO]],'REGIÃO 12 - TRECHOS'!$E$4:$E$76,0)),IFERROR(INDEX('REGIÃO 13 - TRECHOS'!$F$4:$F$53,MATCH(tbResumoR11[[#This Row],[N° TRECHO]],'REGIÃO 13 - TRECHOS'!$E$4:$E$53,0)),"Trecho não cadastrado")))) -> RODOVIA TO-481 - TRECHO DUERÉ - ENTR. TO-181 (CAPAO DO COCO) | J9: Reconformação da plataforma / Recomposição do revestimento primário | K9: ='REGIÃO 11 - HISTÓRICO'!E9 -> 583705.47 | L9: ='REGIÃO 11 - HISTÓRICO'!I9 -> Concluída
B10: ='REGIÃO 11 - HISTÓRICO'!B10 -> 7 | C10: R11 | D10: =_xlfn.XLOOKUP(tbResumoR11[[#This Row],[REGIÃO]],tbRegioes[Código Região],tbRegioes[Contrato],"") -> 049.2024 | E10: ='REGIÃO 11 - HISTÓRICO'!C10 -> 20 | F10: Março | G10: ='REGIÃO 11 - HISTÓRICO'!D10 -> mar/abr/mai | H10: 202 | I10: =IF(tbResumoR11[[#This Row],[N° TRECHO]]="","",IFERROR(INDEX('REGIÃO 11 - TRECHOS'!$F$4:$F$119,MATCH(tbResumoR11[[#This Row],[N° TRECHO]],'REGIÃO 11 - TRECHOS'!$E$4:$E$119,0)),IFERROR(INDEX('REGIÃO 12 - TRECHOS'!$F$4:$F$76,MATCH(tbResumoR11[[#This Row],[N° TRECHO]],'REGIÃO 12 - TRECHOS'!$E$4:$E$76,0)),IFERROR(INDEX('REGIÃO 13 - TRECHOS'!$F$4:$F$53,MATCH(tbResumoR11[[#This Row],[N° TRECHO]],'REGIÃO 13 - TRECHOS'!$E$4:$E$53,0)),"Trecho não cadastrado")))) -> RODOVIA TO-070 - TRECHO SANDOLÂNDIA - FORMOSO DO ARAGUAIA | J10: Roçada | K10: ='REGIÃO 11 - HISTÓRICO'!E10 -> 38576.29 | L10: ='REGIÃO 11 - HISTÓRICO'!I10 -> Concluída
B11: ='REGIÃO 11 - HISTÓRICO'!B11 -> 8 | C11: R11 | D11: =_xlfn.XLOOKUP(tbResumoR11[[#This Row],[REGIÃO]],tbRegioes[Código Região],tbRegioes[Contrato],"") -> 049.2024 | E11: ='REGIÃO 11 - HISTÓRICO'!C11 -> 21 | F11: Março | G11: ='REGIÃO 11 - HISTÓRICO'!D11 -> mar/abr/mai | H11: 209 | I11: =IF(tbResumoR11[[#This Row],[N° TRECHO]]="","",IFERROR(INDEX('REGIÃO 11 - TRECHOS'!$F$4:$F$119,MATCH(tbResumoR11[[#This Row],[N° TRECHO]],'REGIÃO 11 - TRECHOS'!$E$4:$E$119,0)),IFERROR(INDEX('REGIÃO 12 - TRECHOS'!$F$4:$F$76,MATCH(tbResumoR11[[#This Row],[N° TRECHO]],'REGIÃO 12 - TRECHOS'!$E$4:$E$76,0)),IFERROR(INDEX('REGIÃO 13 - TRECHOS'!$F$4:$F$53,MATCH(tbResumoR11[[#This Row],[N° TRECHO]],'REGIÃO 13 - TRECHOS'!$E$4:$E$53,0)),"Trecho não cadastrado")))) -> RODOVIA TO-181 - TRECHO FAZENDA COBRAPE - ENTR. BR-242 | J11: Roçada / Tapa-Buraco CAE | K11: ='REGIÃO 11 - HISTÓRICO'!E11 -> 390709.12 | L11: ='REGIÃO 11 - HISTÓRICO'!I11 -> Concluída
B12: ='REGIÃO 11 - HISTÓRICO'!B12 -> 9 | C12: R11 | D12: =_xlfn.XLOOKUP(tbResumoR11[[#This Row],[REGIÃO]],tbRegioes[Código Região],tbRegioes[Contrato],"") -> 049.2024 | E12: ='REGIÃO 11 - HISTÓRICO'!C12 -> 22 | F12: Março | G12: ='REGIÃO 11 - HISTÓRICO'!D12 -> mar/abr/mai | H12: 210 | I12: =IF(tbResumoR11[[#This Row],[N° TRECHO]]="","",IFERROR(INDEX('REGIÃO 11 - TRECHOS'!$F$4:$F$119,MATCH(tbResumoR11[[#This Row],[N° TRECHO]],'REGIÃO 11 - TRECHOS'!$E$4:$E$119,0)),IFERROR(INDEX('REGIÃO 12 - TRECHOS'!$F$4:$F$76,MATCH(tbResumoR11[[#This Row],[N° TRECHO]],'REGIÃO 12 - TRECHOS'!$E$4:$E$76,0)),IFERROR(INDEX('REGIÃO 13 - TRECHOS'!$F$4:$F$53,MATCH(tbResumoR11[[#This Row],[N° TRECHO]],'REGIÃO 13 - TRECHOS'!$E$4:$E$53,0)),"Trecho não cadastrado")))) -> RODOVIA TO-181 - TRECHO ENTR. BR-242 - FUNDAÇÃO BRADESCO | J12: Roçada / Tapa-Buraco CAE | K12: ='REGIÃO 11 - HISTÓRICO'!E12 -> 318931.06 | L12: ='REGIÃO 11 - HISTÓRICO'!I12 -> Concluída
B13: ='REGIÃO 11 - HISTÓRICO'!B13 -> 10 | C13: R11 | D13: =_xlfn.XLOOKUP(tbResumoR11[[#This Row],[REGIÃO]],tbRegioes[Código Região],tbRegioes[Contrato],"") -> 049.2024 | E13: ='REGIÃO 11 - HISTÓRICO'!C13 -> 23 | F13: Março | G13: ='REGIÃO 11 - HISTÓRICO'!D13 -> mar/abr/mai | H13: 214 | I13: =IF(tbResumoR11[[#This Row],[N° TRECHO]]="","",IFERROR(INDEX('REGIÃO 11 - TRECHOS'!$F$4:$F$119,MATCH(tbResumoR11[[#This Row],[N° TRECHO]],'REGIÃO 11 - TRECHOS'!$E$4:$E$119,0)),IFERROR(INDEX('REGIÃO 12 - TRECHOS'!$F$4:$F$76,MATCH(tbResumoR11[[#This Row],[N° TRECHO]],'REGIÃO 12 - TRECHOS'!$E$4:$E$76,0)),IFERROR(INDEX('REGIÃO 13 - TRECHOS'!$F$4:$F$53,MATCH(tbResumoR11[[#This Row],[N° TRECHO]],'REGIÃO 13 - TRECHOS'!$E$4:$E$53,0)),"Trecho não cadastrado")))) -> RODOVIA TO-362 - TRECHO SANTA RITA DO TOCANTINS - BREJINHO DE NAZARÉ | J13: Terraplenagem / Reconformação da plataforma / Recomposição do revestimento primário | K13: ='REGIÃO 11 - HISTÓRICO'!E13 -> 259096.53 | L13: ='REGIÃO 11 - HISTÓRICO'!I13 -> Cancelada | M13: Em cumprimento ao Termo de Ajustamento de Gestão, com destaque para a Cláusula Segunda, Parágrafo Sexto, é importante ressaltar que, nos anos anteriores, os serviços de manutenção rodoviária foram realizados por meio de Administração Direta, através da Residência Viária de Dianópolis - RV-13. Dessa forma, não há registros históricos disponíveis sobre o desempenho dessas atividades.
B14: ='REGIÃO 11 - HISTÓRICO'!B14 -> 11 | C14: R11 | D14: =_xlfn.XLOOKUP(tbResumoR11[[#This Row],[REGIÃO]],tbRegioes[Código Região],tbRegioes[Contrato],"") -> 049.2024 | E14: ='REGIÃO 11 - HISTÓRICO'!C14 -> 24 | F14: Março | G14: ='REGIÃO 11 - HISTÓRICO'!D14 -> mar/abr/mai | H14: 223 | I14: =IF(tbResumoR11[[#This Row],[N° TRECHO]]="","",IFERROR(INDEX('REGIÃO 11 - TRECHOS'!$F$4:$F$119,MATCH(tbResumoR11[[#This Row],[N° TRECHO]],'REGIÃO 11 - TRECHOS'!$E$4:$E$119,0)),IFERROR(INDEX('REGIÃO 12 - TRECHOS'!$F$4:$F$76,MATCH(tbResumoR11[[#This Row],[N° TRECHO]],'REGIÃO 12 - TRECHOS'!$E$4:$E$76,0)),IFERROR(INDEX('REGIÃO 13 - TRECHOS'!$F$4:$F$53,MATCH(tbResumoR11[[#This Row],[N° TRECHO]],'REGIÃO 13 - TRECHOS'!$E$4:$E$53,0)),"Trecho não cadastrado")))) -> RODOVIA TO-484 - TRECHO FIGUEIRÓPOLIS - KM 64 (RIO FORMOSO) | J14: Reconformação da plataforma / Recomposição do revestimento primário | K14: ='REGIÃO 11 - HISTÓRICO'!E14 -> 86715.58 | L14: ='REGIÃO 11 - HISTÓRICO'!I14 -> Cancelada | M14: Em cumprimento ao Termo de Ajustamento de Gestão, com destaque para a Cláusula Segunda, Parágrafo Sexto, é importante ressaltar que, nos anos anteriores, os serviços de manutenção rodoviária foram realizados por meio de Administração Direta, através da Residência Viária de Dianópolis - RV-13. Dessa forma, não há registros históricos disponíveis sobre o desempenho dessas atividades.
B15: ='REGIÃO 11 - HISTÓRICO'!B15 -> 12 | C15: R11 | D15: =_xlfn.XLOOKUP(tbResumoR11[[#This Row],[REGIÃO]],tbRegioes[Código Região],tbRegioes[Contrato],"") -> 049.2024 | E15: ='REGIÃO 11 - HISTÓRICO'!C15 -> 25 | F15: Março | G15: ='REGIÃO 11 - HISTÓRICO'!D15 -> mar | H15: 204 | I15: =IF(tbResumoR11[[#This Row],[N° TRECHO]]="","",IFERROR(INDEX('REGIÃO 11 - TRECHOS'!$F$4:$F$119,MATCH(tbResumoR11[[#This Row],[N° TRECHO]],'REGIÃO 11 - TRECHOS'!$E$4:$E$119,0)),IFERROR(INDEX('REGIÃO 12 - TRECHOS'!$F$4:$F$76,MATCH(tbResumoR11[[#This Row],[N° TRECHO]],'REGIÃO 12 - TRECHOS'!$E$4:$E$76,0)),IFERROR(INDEX('REGIÃO 13 - TRECHOS'!$F$4:$F$53,MATCH(tbResumoR11[[#This Row],[N° TRECHO]],'REGIÃO 13 - TRECHOS'!$E$4:$E$53,0)),"Trecho não cadastrado")))) -> RODOVIA TO-070 - TRECHO ALIANÇA DO TOCANTINS - BREJINHO DE NAZARÉ | J15: SERVIÇOS MANUTENÇÃO | K15: ='REGIÃO 11 - HISTÓRICO'!E15 -> 3173.97 | L15: ='REGIÃO 11 - HISTÓRICO'!I15 -> Concluída
B16: ='REGIÃO 11 - HISTÓRICO'!B16 -> 13 | C16: R11 | D16: =_xlfn.XLOOKUP(tbResumoR11[[#This Row],[REGIÃO]],tbRegioes[Código Região],tbRegioes[Contrato],"") -> 049.2024 | E16: ='REGIÃO 11 - HISTÓRICO'!C16 -> 26 | F16: Abril | G16: ='REGIÃO 11 - HISTÓRICO'!D16 -> abr/mai | H16: 204 | I16: =IF(tbResumoR11[[#This Row],[N° TRECHO]]="","",IFERROR(INDEX('REGIÃO 11 - TRECHOS'!$F$4:$F$119,MATCH(tbResumoR11[[#This Row],[N° TRECHO]],'REGIÃO 11 - TRECHOS'!$E$4:$E$119,0)),IFERROR(INDEX('REGIÃO 12 - TRECHOS'!$F$4:$F$76,MATCH(tbResumoR11[[#This Row],[N° TRECHO]],'REGIÃO 12 - TRECHOS'!$E$4:$E$76,0)),IFERROR(INDEX('REGIÃO 13 - TRECHOS'!$F$4:$F$53,MATCH(tbResumoR11[[#This Row],[N° TRECHO]],'REGIÃO 13 - TRECHOS'!$E$4:$E$53,0)),"Trecho não cadastrado")))) -> RODOVIA TO-070 - TRECHO ALIANÇA DO TOCANTINS - BREJINHO DE NAZARÉ | J16: Tapa-Buraco CAE | K16: ='REGIÃO 11 - HISTÓRICO'!E16 -> 31085.39 | L16: ='REGIÃO 11 - HISTÓRICO'!I16 -> Concluída
B17: ='REGIÃO 11 - HISTÓRICO'!B17 -> 14 | C17: R11 | D17: =_xlfn.XLOOKUP(tbResumoR11[[#This Row],[REGIÃO]],tbRegioes[Código Região],tbRegioes[Contrato],"") -> 049.2024 | E17: ='REGIÃO 11 - HISTÓRICO'!C17 -> 27 | F17: Abril | G17: ='REGIÃO 11 - HISTÓRICO'!D17 -> abr/mai | H17: 206 | I17: =IF(tbResumoR11[[#This Row],[N° TRECHO]]="","",IFERROR(INDEX('REGIÃO 11 - TRECHOS'!$F$4:$F$119,MATCH(tbResumoR11[[#This Row],[N° TRECHO]],'REGIÃO 11 - TRECHOS'!$E$4:$E$119,0)),IFERROR(INDEX('REGIÃO 12 - TRECHOS'!$F$4:$F$76,MATCH(tbResumoR11[[#This Row],[N° TRECHO]],'REGIÃO 12 - TRECHOS'!$E$4:$E$76,0)),IFERROR(INDEX('REGIÃO 13 - TRECHOS'!$F$4:$F$53,MATCH(tbResumoR11[[#This Row],[N° TRECHO]],'REGIÃO 13 - TRECHOS'!$E$4:$E$53,0)),"Trecho não cadastrado")))) -> RODOVIA TO-070 - TRECHO FORMOSO DO ARAGUAIA - DUERÉ | J17: Roçada | K17: ='REGIÃO 11 - HISTÓRICO'!E17 -> 32173.84 | L17: ='REGIÃO 11 - HISTÓRICO'!I17 -> Concluída
B18: ='REGIÃO 11 - HISTÓRICO'!B18 -> 15 | C18: R11 | D18: =_xlfn.XLOOKUP(tbResumoR11[[#This Row],[REGIÃO]],tbRegioes[Código Região],tbRegioes[Contrato],"") -> 049.2024 | E18: ='REGIÃO 11 - HISTÓRICO'!C18 -> 28 | F18: Maio | G18: ='REGIÃO 11 - HISTÓRICO'!D18 -> mai/jun | H18: 204 | I18: =IF(tbResumoR11[[#This Row],[N° TRECHO]]="","",IFERROR(INDEX('REGIÃO 11 - TRECHOS'!$F$4:$F$119,MATCH(tbResumoR11[[#This Row],[N° TRECHO]],'REGIÃO 11 - TRECHOS'!$E$4:$E$119,0)),IFERROR(INDEX('REGIÃO 12 - TRECHOS'!$F$4:$F$76,MATCH(tbResumoR11[[#This Row],[N° TRECHO]],'REGIÃO 12 - TRECHOS'!$E$4:$E$76,0)),IFERROR(INDEX('REGIÃO 13 - TRECHOS'!$F$4:$F$53,MATCH(tbResumoR11[[#This Row],[N° TRECHO]],'REGIÃO 13 - TRECHOS'!$E$4:$E$53,0)),"Trecho não cadastrado")))) -> RODOVIA TO-070 - TRECHO ALIANÇA DO TOCANTINS - BREJINHO DE NAZARÉ | J18: Limpeza EDS / Caiação de EDS e pontes | K18: ='REGIÃO 11 - HISTÓRICO'!E18 -> 23752.58 | L18: ='REGIÃO 11 - HISTÓRICO'!I18 -> Cancelada | M18: Em cumprimento ao Termo de Ajustamento de Gestão, com destaque para a Cláusula Segunda, Parágrafo Sexto, é importante ressaltar que, nos anos anteriores, os serviços de manutenção rodoviária foram realizados por meio de Administração Direta da Residencia Viaria de Gurupi . Dessa forma, não há registros históricos disponíveis sobre o desempenho dessas atividades. Dessa forma, os serviços propostos são fundamentais para a durabilidade das estruturas, redução de riscos e eficiência operacional das vias públicas e rodoviárias.
B19: ='REGIÃO 11 - HISTÓRICO'!B19 -> 16 | C19: R11 | D19: =_xlfn.XLOOKUP(tbResumoR11[[#This Row],[REGIÃO]],tbRegioes[Código Região],tbRegioes[Contrato],"") -> 049.2024 | E19: ='REGIÃO 11 - HISTÓRICO'!C19 -> 29 | F19: Maio | G19: ='REGIÃO 11 - HISTÓRICO'!D19 -> mai/jun/jul | H19: 205 | I19: =IF(tbResumoR11[[#This Row],[N° TRECHO]]="","",IFERROR(INDEX('REGIÃO 11 - TRECHOS'!$F$4:$F$119,MATCH(tbResumoR11[[#This Row],[N° TRECHO]],'REGIÃO 11 - TRECHOS'!$E$4:$E$119,0)),IFERROR(INDEX('REGIÃO 12 - TRECHOS'!$F$4:$F$76,MATCH(tbResumoR11[[#This Row],[N° TRECHO]],'REGIÃO 12 - TRECHOS'!$E$4:$E$76,0)),IFERROR(INDEX('REGIÃO 13 - TRECHOS'!$F$4:$F$53,MATCH(tbResumoR11[[#This Row],[N° TRECHO]],'REGIÃO 13 - TRECHOS'!$E$4:$E$53,0)),"Trecho não cadastrado")))) -> RODOVIA TO-070 - TRECHO DUERÉ - ALIANÇA DO TOCANTINS | J19: Roçada | K19: ='REGIÃO 11 - HISTÓRICO'!E19 -> 16378.85 | L19: ='REGIÃO 11 - HISTÓRICO'!I19 -> Concluída
B20: ='REGIÃO 11 - HISTÓRICO'!B20 -> 17 | C20: R11 | D20: =_xlfn.XLOOKUP(tbResumoR11[[#This Row],[REGIÃO]],tbRegioes[Código Região],tbRegioes[Contrato],"") -> 049.2024 | E20: ='REGIÃO 11 - HISTÓRICO'!C20 -> 30 | F20: Maio | G20: ='REGIÃO 11 - HISTÓRICO'!D20 -> mai/jun/jul | H20: 218 | I20: =IF(tbResumoR11[[#This Row],[N° TRECHO]]="","",IFERROR(INDEX('REGIÃO 11 - TRECHOS'!$F$4:$F$119,MATCH(tbResumoR11[[#This Row],[N° TRECHO]],'REGIÃO 11 - TRECHOS'!$E$4:$E$119,0)),IFERROR(INDEX('REGIÃO 12 - TRECHOS'!$F$4:$F$76,MATCH(tbResumoR11[[#This Row],[N° TRECHO]],'REGIÃO 12 - TRECHOS'!$E$4:$E$76,0)),IFERROR(INDEX('REGIÃO 13 - TRECHOS'!$F$4:$F$53,MATCH(tbResumoR11[[#This Row],[N° TRECHO]],'REGIÃO 13 - TRECHOS'!$E$4:$E$53,0)),"Trecho não cadastrado")))) -> RODOVIA TO-373 - TRECHO ALVORADA - ARAGUAÇU - DIVISA TO-GO | J20: Roçada | K20: ='REGIÃO 11 - HISTÓRICO'!E20 -> 39853.56 | L20: ='REGIÃO 11 - HISTÓRICO'!I20 -> Concluída
B21: ='REGIÃO 11 - HISTÓRICO'!B21 -> 18 | C21: R11 | D21: =_xlfn.XLOOKUP(tbResumoR11[[#This Row],[REGIÃO]],tbRegioes[Código Região],tbRegioes[Contrato],"") -> 049.2024 | E21: ='REGIÃO 11 - HISTÓRICO'!C21 -> 31 | F21: Maio | G21: ='REGIÃO 11 - HISTÓRICO'!D21 -> mai/jun/jul | H21: 219 | I21: =IF(tbResumoR11[[#This Row],[N° TRECHO]]="","",IFERROR(INDEX('REGIÃO 11 - TRECHOS'!$F$4:$F$119,MATCH(tbResumoR11[[#This Row],[N° TRECHO]],'REGIÃO 11 - TRECHOS'!$E$4:$E$119,0)),IFERROR(INDEX('REGIÃO 12 - TRECHOS'!$F$4:$F$76,MATCH(tbResumoR11[[#This Row],[N° TRECHO]],'REGIÃO 12 - TRECHOS'!$E$4:$E$76,0)),IFERROR(INDEX('REGIÃO 13 - TRECHOS'!$F$4:$F$53,MATCH(tbResumoR11[[#This Row],[N° TRECHO]],'REGIÃO 13 - TRECHOS'!$E$4:$E$53,0)),"Trecho não cadastrado")))) -> RODOVIA TO-374 - TRECHO DUERÉ - GURUPI | J21: Roçada | K21: ='REGIÃO 11 - HISTÓRICO'!E21 -> 18928.21 | L21: ='REGIÃO 11 - HISTÓRICO'!I21 -> Concluída
B22: ='REGIÃO 11 - HISTÓRICO'!B22 -> 19 | C22: R11 | D22: =_xlfn.XLOOKUP(tbResumoR11[[#This Row],[REGIÃO]],tbRegioes[Código Região],tbRegioes[Contrato],"") -> 049.2024 | E22: ='REGIÃO 11 - HISTÓRICO'!C22 -> 32 | F22: Maio | G22: ='REGIÃO 11 - HISTÓRICO'!D22 -> mai/jun | H22: 204 | I22: =IF(tbResumoR11[[#This Row],[N° TRECHO]]="","",IFERROR(INDEX('REGIÃO 11 - TRECHOS'!$F$4:$F$119,MATCH(tbResumoR11[[#This Row],[N° TRECHO]],'REGIÃO 11 - TRECHOS'!$E$4:$E$119,0)),IFERROR(INDEX('REGIÃO 12 - TRECHOS'!$F$4:$F$76,MATCH(tbResumoR11[[#This Row],[N° TRECHO]],'REGIÃO 12 - TRECHOS'!$E$4:$E$76,0)),IFERROR(INDEX('REGIÃO 13 - TRECHOS'!$F$4:$F$53,MATCH(tbResumoR11[[#This Row],[N° TRECHO]],'REGIÃO 13 - TRECHOS'!$E$4:$E$53,0)),"Trecho não cadastrado")))) -> RODOVIA TO-070 - TRECHO ALIANÇA DO TOCANTINS - BREJINHO DE NAZARÉ | J22: Roçada / Remendo profundo | K22: ='REGIÃO 11 - HISTÓRICO'!E22 -> 37930.29 | L22: ='REGIÃO 11 - HISTÓRICO'!I22 -> Concluída
B23: ='REGIÃO 11 - HISTÓRICO'!B23 -> 20 | C23: R11 | D23: =_xlfn.XLOOKUP(tbResumoR11[[#This Row],[REGIÃO]],tbRegioes[Código Região],tbRegioes[Contrato],"") -> 049.2024 | E23: ='REGIÃO 11 - HISTÓRICO'!C23 -> 33 | F23: Maio | G23: ='REGIÃO 11 - HISTÓRICO'!D23 -> mai/jun | H23: 216 | I23: =IF(tbResumoR11[[#This Row],[N° TRECHO]]="","",IFERROR(INDEX('REGIÃO 11 - TRECHOS'!$F$4:$F$119,MATCH(tbResumoR11[[#This Row],[N° TRECHO]],'REGIÃO 11 - TRECHOS'!$E$4:$E$119,0)),IFERROR(INDEX('REGIÃO 12 - TRECHOS'!$F$4:$F$76,MATCH(tbResumoR11[[#This Row],[N° TRECHO]],'REGIÃO 12 - TRECHOS'!$E$4:$E$76,0)),IFERROR(INDEX('REGIÃO 13 - TRECHOS'!$F$4:$F$53,MATCH(tbResumoR11[[#This Row],[N° TRECHO]],'REGIÃO 13 - TRECHOS'!$E$4:$E$53,0)),"Trecho não cadastrado")))) -> RODOVIA TO-365 - TRECHO RIO TOCANTINS (BALSA) - TREVO DA PRAIA - ENTR. BR-153 | J23: Roçada | K23: ='REGIÃO 11 - HISTÓRICO'!E23 -> 21028 | L23: ='REGIÃO 11 - HISTÓRICO'!I23 -> Concluída
B24: ='REGIÃO 11 - HISTÓRICO'!B24 -> 21 | C24: R11 | D24: =_xlfn.XLOOKUP(tbResumoR11[[#This Row],[REGIÃO]],tbRegioes[Código Região],tbRegioes[Contrato],"") -> 049.2024 | E24: ='REGIÃO 11 - HISTÓRICO'!C24 -> 34 | F24: Junho | G24: ='REGIÃO 11 - HISTÓRICO'!D24 -> jun/jul | H24: 208 | I24: =IF(tbResumoR11[[#This Row],[N° TRECHO]]="","",IFERROR(INDEX('REGIÃO 11 - TRECHOS'!$F$4:$F$119,MATCH(tbResumoR11[[#This Row],[N° TRECHO]],'REGIÃO 11 - TRECHOS'!$E$4:$E$119,0)),IFERROR(INDEX('REGIÃO 12 - TRECHOS'!$F$4:$F$76,MATCH(tbResumoR11[[#This Row],[N° TRECHO]],'REGIÃO 12 - TRECHOS'!$E$4:$E$76,0)),IFERROR(INDEX('REGIÃO 13 - TRECHOS'!$F$4:$F$53,MATCH(tbResumoR11[[#This Row],[N° TRECHO]],'REGIÃO 13 - TRECHOS'!$E$4:$E$53,0)),"Trecho não cadastrado")))) -> RODOVIA TO-181 - TRECHO ENTR. TO-481 (CAPAO DO COCO) - FAZENDA COBRAPE | J24: Terraplenagem / Reconformação da plataforma / Recomposição do revestimento primário | K24: ='REGIÃO 11 - HISTÓRICO'!E24 -> 592238.52 | L24: ='REGIÃO 11 - HISTÓRICO'!I24 -> Concluída
B25: ='REGIÃO 11 - HISTÓRICO'!B25 -> 22 | C25: R11 | D25: =_xlfn.XLOOKUP(tbResumoR11[[#This Row],[REGIÃO]],tbRegioes[Código Região],tbRegioes[Contrato],"") -> 049.2024 | E25: ='REGIÃO 11 - HISTÓRICO'!C25 -> 35 | F25: Junho | G25: ='REGIÃO 11 - HISTÓRICO'!D25 -> jun/jul | H25: 210 | I25: =IF(tbResumoR11[[#This Row],[N° TRECHO]]="","",IFERROR(INDEX('REGIÃO 11 - TRECHOS'!$F$4:$F$119,MATCH(tbResumoR11[[#This Row],[N° TRECHO]],'REGIÃO 11 - TRECHOS'!$E$4:$E$119,0)),IFERROR(INDEX('REGIÃO 12 - TRECHOS'!$F$4:$F$76,MATCH(tbResumoR11[[#This Row],[N° TRECHO]],'REGIÃO 12 - TRECHOS'!$E$4:$E$76,0)),IFERROR(INDEX('REGIÃO 13 - TRECHOS'!$F$4:$F$53,MATCH(tbResumoR11[[#This Row],[N° TRECHO]],'REGIÃO 13 - TRECHOS'!$E$4:$E$53,0)),"Trecho não cadastrado")))) -> RODOVIA TO-181 - TRECHO ENTR. BR-242 - FUNDAÇÃO BRADESCO | J25: Tapa-Buraco CAE | K25: ='REGIÃO 11 - HISTÓRICO'!E25 -> 34721.02 | L25: ='REGIÃO 11 - HISTÓRICO'!I25 -> Concluída
B26: ='REGIÃO 11 - HISTÓRICO'!B26 -> 23 | C26: R11 | D26: =_xlfn.XLOOKUP(tbResumoR11[[#This Row],[REGIÃO]],tbRegioes[Código Região],tbRegioes[Contrato],"") -> 049.2024 | E26: ='REGIÃO 11 - HISTÓRICO'!C26 -> 36 | F26: Agosto | G26: ='REGIÃO 11 - HISTÓRICO'!D26 -> ago/set/out | H26: 202 | I26: =IF(tbResumoR11[[#This Row],[N° TRECHO]]="","",IFERROR(INDEX('REGIÃO 11 - TRECHOS'!$F$4:$F$119,MATCH(tbResumoR11[[#This Row],[N° TRECHO]],'REGIÃO 11 - TRECHOS'!$E$4:$E$119,0)),IFERROR(INDEX('REGIÃO 12 - TRECHOS'!$F$4:$F$76,MATCH(tbResumoR11[[#This Row],[N° TRECHO]],'REGIÃO 12 - TRECHOS'!$E$4:$E$76,0)),IFERROR(INDEX('REGIÃO 13 - TRECHOS'!$F$4:$F$53,MATCH(tbResumoR11[[#This Row],[N° TRECHO]],'REGIÃO 13 - TRECHOS'!$E$4:$E$53,0)),"Trecho não cadastrado")))) -> RODOVIA TO-070 - TRECHO SANDOLÂNDIA - FORMOSO DO ARAGUAIA | J26: Roçada | K26: ='REGIÃO 11 - HISTÓRICO'!E26 -> 52055.37 | L26: ='REGIÃO 11 - HISTÓRICO'!I26 -> Concluída
B27: ='REGIÃO 11 - HISTÓRICO'!B27 -> 24 | C27: R11 | D27: =_xlfn.XLOOKUP(tbResumoR11[[#This Row],[REGIÃO]],tbRegioes[Código Região],tbRegioes[Contrato],"") -> 049.2024 | E27: ='REGIÃO 11 - HISTÓRICO'!C27 -> 37 | F27: Agosto | G27: ='REGIÃO 11 - HISTÓRICO'!D27 -> ago/set | H27: 212 | I27: =IF(tbResumoR11[[#This Row],[N° TRECHO]]="","",IFERROR(INDEX('REGIÃO 11 - TRECHOS'!$F$4:$F$119,MATCH(tbResumoR11[[#This Row],[N° TRECHO]],'REGIÃO 11 - TRECHOS'!$E$4:$E$119,0)),IFERROR(INDEX('REGIÃO 12 - TRECHOS'!$F$4:$F$76,MATCH(tbResumoR11[[#This Row],[N° TRECHO]],'REGIÃO 12 - TRECHOS'!$E$4:$E$76,0)),IFERROR(INDEX('REGIÃO 13 - TRECHOS'!$F$4:$F$53,MATCH(tbResumoR11[[#This Row],[N° TRECHO]],'REGIÃO 13 - TRECHOS'!$E$4:$E$53,0)),"Trecho não cadastrado")))) -> RODOVIA TO-181 - TRECHO ARAGUAÇU - SANDOLÂNDIA | J27: Roçada | K27: ='REGIÃO 11 - HISTÓRICO'!E27 -> 25053.71 | L27: ='REGIÃO 11 - HISTÓRICO'!I27 -> Concluída
B28: ='REGIÃO 11 - HISTÓRICO'!B28 -> 25 | C28: R11 | D28: =_xlfn.XLOOKUP(tbResumoR11[[#This Row],[REGIÃO]],tbRegioes[Código Região],tbRegioes[Contrato],"") -> 049.2024 | E28: ='REGIÃO 11 - HISTÓRICO'!C28 -> 38 | F28: Agosto | G28: ='REGIÃO 11 - HISTÓRICO'!D28 -> ago/set | H28: 218 | I28: =IF(tbResumoR11[[#This Row],[N° TRECHO]]="","",IFERROR(INDEX('REGIÃO 11 - TRECHOS'!$F$4:$F$119,MATCH(tbResumoR11[[#This Row],[N° TRECHO]],'REGIÃO 11 - TRECHOS'!$E$4:$E$119,0)),IFERROR(INDEX('REGIÃO 12 - TRECHOS'!$F$4:$F$76,MATCH(tbResumoR11[[#This Row],[N° TRECHO]],'REGIÃO 12 - TRECHOS'!$E$4:$E$76,0)),IFERROR(INDEX('REGIÃO 13 - TRECHOS'!$F$4:$F$53,MATCH(tbResumoR11[[#This Row],[N° TRECHO]],'REGIÃO 13 - TRECHOS'!$E$4:$E$53,0)),"Trecho não cadastrado")))) -> RODOVIA TO-373 - TRECHO ALVORADA - ARAGUAÇU - DIVISA TO-GO | J28: Roçada | K28: ='REGIÃO 11 - HISTÓRICO'!E28 -> 54614.53 | L28: ='REGIÃO 11 - HISTÓRICO'!I28 -> Cancelada | M28: O serviço de roçagem e poda nas rodovias é fundamental para garantir a segurança viária, pois melhora a visibilidade da sinalização, evita o esconderijo de animais que podem invadir a pista e reduz o risco de incêndios causados por vegetação seca. Além disso, contribui para a conservação da estrada e para a estética da via.
B29: ='REGIÃO 11 - HISTÓRICO'!B29 -> 26 | C29: R11 | D29: =_xlfn.XLOOKUP(tbResumoR11[[#This Row],[REGIÃO]],tbRegioes[Código Região],tbRegioes[Contrato],"") -> 049.2024 | E29: ='REGIÃO 11 - HISTÓRICO'!C29 -> 39 | F29: Julho | G29: ='REGIÃO 11 - HISTÓRICO'!D29 -> jul/ago/set | H29: 204 | I29: =IF(tbResumoR11[[#This Row],[N° TRECHO]]="","",IFERROR(INDEX('REGIÃO 11 - TRECHOS'!$F$4:$F$119,MATCH(tbResumoR11[[#This Row],[N° TRECHO]],'REGIÃO 11 - TRECHOS'!$E$4:$E$119,0)),IFERROR(INDEX('REGIÃO 12 - TRECHOS'!$F$4:$F$76,MATCH(tbResumoR11[[#This Row],[N° TRECHO]],'REGIÃO 12 - TRECHOS'!$E$4:$E$76,0)),IFERROR(INDEX('REGIÃO 13 - TRECHOS'!$F$4:$F$53,MATCH(tbResumoR11[[#This Row],[N° TRECHO]],'REGIÃO 13 - TRECHOS'!$E$4:$E$53,0)),"Trecho não cadastrado")))) -> RODOVIA TO-070 - TRECHO ALIANÇA DO TOCANTINS - BREJINHO DE NAZARÉ | J29: Roçada / Tapa-Buraco PMF | K29: ='REGIÃO 11 - HISTÓRICO'!E29 -> 49869.41 | L29: ='REGIÃO 11 - HISTÓRICO'!I29 -> Justificada
B30: ='REGIÃO 11 - HISTÓRICO'!B31 -> 28 | C30: R11 | D30: =_xlfn.XLOOKUP(tbResumoR11[[#This Row],[REGIÃO]],tbRegioes[Código Região],tbRegioes[Contrato],"") -> 049.2024 | E30: ='REGIÃO 11 - HISTÓRICO'!C30 -> 40 | F30: Outubro | G30: ='REGIÃO 11 - HISTÓRICO'!D30 -> out | H30: 204 | I30: =IF(tbResumoR11[[#This Row],[N° TRECHO]]="","",IFERROR(INDEX('REGIÃO 11 - TRECHOS'!$F$4:$F$119,MATCH(tbResumoR11[[#This Row],[N° TRECHO]],'REGIÃO 11 - TRECHOS'!$E$4:$E$119,0)),IFERROR(INDEX('REGIÃO 12 - TRECHOS'!$F$4:$F$76,MATCH(tbResumoR11[[#This Row],[N° TRECHO]],'REGIÃO 12 - TRECHOS'!$E$4:$E$76,0)),IFERROR(INDEX('REGIÃO 13 - TRECHOS'!$F$4:$F$53,MATCH(tbResumoR11[[#This Row],[N° TRECHO]],'REGIÃO 13 - TRECHOS'!$E$4:$E$53,0)),"Trecho não cadastrado")))) -> RODOVIA TO-070 - TRECHO ALIANÇA DO TOCANTINS - BREJINHO DE NAZARÉ | J30: Caiação de EDS e pontes | K30: ='REGIÃO 11 - HISTÓRICO'!E30 -> 2026.6 | L30: ='REGIÃO 11 - HISTÓRICO'!I30 -> Em elaboração
B31: ='REGIÃO 11 - HISTÓRICO'!B32 -> 29 | C31: R11 | D31: =_xlfn.XLOOKUP(tbResumoR11[[#This Row],[REGIÃO]],tbRegioes[Código Região],tbRegioes[Contrato],"") -> 049.2024 | E31: ='REGIÃO 11 - HISTÓRICO'!C31 -> 41 | F31: Agosto | G31: ='REGIÃO 11 - HISTÓRICO'!D31 -> ago/set | H31: 220 | I31: =IF(tbResumoR11[[#This Row],[N° TRECHO]]="","",IFERROR(INDEX('REGIÃO 11 - TRECHOS'!$F$4:$F$119,MATCH(tbResumoR11[[#This Row],[N° TRECHO]],'REGIÃO 11 - TRECHOS'!$E$4:$E$119,0)),IFERROR(INDEX('REGIÃO 12 - TRECHOS'!$F$4:$F$76,MATCH(tbResumoR11[[#This Row],[N° TRECHO]],'REGIÃO 12 - TRECHOS'!$E$4:$E$76,0)),IFERROR(INDEX('REGIÃO 13 - TRECHOS'!$F$4:$F$53,MATCH(tbResumoR11[[#This Row],[N° TRECHO]],'REGIÃO 13 - TRECHOS'!$E$4:$E$53,0)),"Trecho não cadastrado")))) -> RODOVIA TO-460 - TRECHO BR-242 (VILA QUIXABA) - SUCUPIRA | J31: Roçada | K31: ='REGIÃO 11 - HISTÓRICO'!E31 -> 7327.54 | L31: ='REGIÃO 11 - HISTÓRICO'!I31 -> Concluída
B32: ='REGIÃO 11 - HISTÓRICO'!B33 -> 30 | C32: R11 | D32: =_xlfn.XLOOKUP(tbResumoR11[[#This Row],[REGIÃO]],tbRegioes[Código Região],tbRegioes[Contrato],"") -> 049.2024 | E32: ='REGIÃO 11 - HISTÓRICO'!C32 -> 42 | F32: Agosto | G32: ='REGIÃO 11 - HISTÓRICO'!D32 -> ago/set | H32: 214 | I32: =IF(tbResumoR11[[#This Row],[N° TRECHO]]="","",IFERROR(INDEX('REGIÃO 11 - TRECHOS'!$F$4:$F$119,MATCH(tbResumoR11[[#This Row],[N° TRECHO]],'REGIÃO 11 - TRECHOS'!$E$4:$E$119,0)),IFERROR(INDEX('REGIÃO 12 - TRECHOS'!$F$4:$F$76,MATCH(tbResumoR11[[#This Row],[N° TRECHO]],'REGIÃO 12 - TRECHOS'!$E$4:$E$76,0)),IFERROR(INDEX('REGIÃO 13 - TRECHOS'!$F$4:$F$53,MATCH(tbResumoR11[[#This Row],[N° TRECHO]],'REGIÃO 13 - TRECHOS'!$E$4:$E$53,0)),"Trecho não cadastrado")))) -> RODOVIA TO-362 - TRECHO SANTA RITA DO TOCANTINS - BREJINHO DE NAZARÉ | J32: Reconformação da plataforma | K32: ='REGIÃO 11 - HISTÓRICO'!E32 -> 48592.65 | L32: ='REGIÃO 11 - HISTÓRICO'!I32 -> Justificada
B33: ='REGIÃO 11 - HISTÓRICO'!B34 -> 31 | C33: R11 | D33: =_xlfn.XLOOKUP(tbResumoR11[[#This Row],[REGIÃO]],tbRegioes[Código Região],tbRegioes[Contrato],"") -> 049.2024 | E33: ='REGIÃO 11 - HISTÓRICO'!C33 -> 43 | F33: Setembro | G33: ='REGIÃO 11 - HISTÓRICO'!D33 -> set/out | H33: 215 | I33: =IF(tbResumoR11[[#This Row],[N° TRECHO]]="","",IFERROR(INDEX('REGIÃO 11 - TRECHOS'!$F$4:$F$119,MATCH(tbResumoR11[[#This Row],[N° TRECHO]],'REGIÃO 11 - TRECHOS'!$E$4:$E$119,0)),IFERROR(INDEX('REGIÃO 12 - TRECHOS'!$F$4:$F$76,MATCH(tbResumoR11[[#This Row],[N° TRECHO]],'REGIÃO 12 - TRECHOS'!$E$4:$E$76,0)),IFERROR(INDEX('REGIÃO 13 - TRECHOS'!$F$4:$F$53,MATCH(tbResumoR11[[#This Row],[N° TRECHO]],'REGIÃO 13 - TRECHOS'!$E$4:$E$53,0)),"Trecho não cadastrado")))) -> RODOVIA TO-362 - TRECHO BREJINHO DE NAZARÉ - ENTR. TO-365 (ACESSO BALSA) | J33: Reconformação da plataforma | K33: ='REGIÃO 11 - HISTÓRICO'!E33 -> 39048.17 | L33: ='REGIÃO 11 - HISTÓRICO'!I33 -> Em elaboração
B34: ='REGIÃO 11 - HISTÓRICO'!B35 -> 32 | C34: R11 | D34: =_xlfn.XLOOKUP(tbResumoR11[[#This Row],[REGIÃO]],tbRegioes[Código Região],tbRegioes[Contrato],"") -> 049.2024 | E34: ='REGIÃO 11 - HISTÓRICO'!C34 -> 44 | F34: Setembro | G34: ='REGIÃO 11 - HISTÓRICO'!D34 -> set/out | H34: 216 | I34: =IF(tbResumoR11[[#This Row],[N° TRECHO]]="","",IFERROR(INDEX('REGIÃO 11 - TRECHOS'!$F$4:$F$119,MATCH(tbResumoR11[[#This Row],[N° TRECHO]],'REGIÃO 11 - TRECHOS'!$E$4:$E$119,0)),IFERROR(INDEX('REGIÃO 12 - TRECHOS'!$F$4:$F$76,MATCH(tbResumoR11[[#This Row],[N° TRECHO]],'REGIÃO 12 - TRECHOS'!$E$4:$E$76,0)),IFERROR(INDEX('REGIÃO 13 - TRECHOS'!$F$4:$F$53,MATCH(tbResumoR11[[#This Row],[N° TRECHO]],'REGIÃO 13 - TRECHOS'!$E$4:$E$53,0)),"Trecho não cadastrado")))) -> RODOVIA TO-365 - TRECHO RIO TOCANTINS (BALSA) - TREVO DA PRAIA - ENTR. BR-153 | J34: Reconformação da plataforma | K34: ='REGIÃO 11 - HISTÓRICO'!E34 -> 36149.23 | L34: ='REGIÃO 11 - HISTÓRICO'!I34 -> Em elaboração
B35: ='REGIÃO 11 - HISTÓRICO'!B36 -> 33 | C35: R11 | D35: =_xlfn.XLOOKUP(tbResumoR11[[#This Row],[REGIÃO]],tbRegioes[Código Região],tbRegioes[Contrato],"") -> 049.2024 | E35: ='REGIÃO 11 - HISTÓRICO'!C35 -> 45 | F35: Agosto | G35: ='REGIÃO 11 - HISTÓRICO'!D35 -> ago/set | H35: 221 | I35: =IF(tbResumoR11[[#This Row],[N° TRECHO]]="","",IFERROR(INDEX('REGIÃO 11 - TRECHOS'!$F$4:$F$119,MATCH(tbResumoR11[[#This Row],[N° TRECHO]],'REGIÃO 11 - TRECHOS'!$E$4:$E$119,0)),IFERROR(INDEX('REGIÃO 12 - TRECHOS'!$F$4:$F$76,MATCH(tbResumoR11[[#This Row],[N° TRECHO]],'REGIÃO 12 - TRECHOS'!$E$4:$E$76,0)),IFERROR(INDEX('REGIÃO 13 - TRECHOS'!$F$4:$F$53,MATCH(tbResumoR11[[#This Row],[N° TRECHO]],'REGIÃO 13 - TRECHOS'!$E$4:$E$53,0)),"Trecho não cadastrado")))) -> RODOVIA TO-481 - TRECHO DUERÉ - ENTR. TO-181 (CAPAO DO COCO) | J35: Reconformação da plataforma | K35: ='REGIÃO 11 - HISTÓRICO'!E35 -> 82686.17 | L35: ='REGIÃO 11 - HISTÓRICO'!I35 -> Concluída
B36: ='REGIÃO 11 - HISTÓRICO'!B36 -> 33 | C36: R11 | D36: =_xlfn.XLOOKUP(tbResumoR11[[#This Row],[REGIÃO]],tbRegioes[Código Região],tbRegioes[Contrato],"") -> 049.2024 | E36: ='REGIÃO 11 - HISTÓRICO'!C36 -> 46 | F36: Outubro | G36: ='REGIÃO 11 - HISTÓRICO'!D36 -> out | H36: 206 | I36: =IF(tbResumoR11[[#This Row],[N° TRECHO]]="","",IFERROR(INDEX('REGIÃO 11 - TRECHOS'!$F$4:$F$119,MATCH(tbResumoR11[[#This Row],[N° TRECHO]],'REGIÃO 11 - TRECHOS'!$E$4:$E$119,0)),IFERROR(INDEX('REGIÃO 12 - TRECHOS'!$F$4:$F$76,MATCH(tbResumoR11[[#This Row],[N° TRECHO]],'REGIÃO 12 - TRECHOS'!$E$4:$E$76,0)),IFERROR(INDEX('REGIÃO 13 - TRECHOS'!$F$4:$F$53,MATCH(tbResumoR11[[#This Row],[N° TRECHO]],'REGIÃO 13 - TRECHOS'!$E$4:$E$53,0)),"Trecho não cadastrado")))) -> RODOVIA TO-070 - TRECHO FORMOSO DO ARAGUAIA - DUERÉ | J36: Caiação de EDS e pontes | K36: ='REGIÃO 11 - HISTÓRICO'!E36 -> 2279.68 | L36: ='REGIÃO 11 - HISTÓRICO'!I36 -> Em elaboração
B37: ='REGIÃO 11 - HISTÓRICO'!B37 -> 34 | C37: R11 | D37: =_xlfn.XLOOKUP(tbResumoR11[[#This Row],[REGIÃO]],tbRegioes[Código Região],tbRegioes[Contrato],"") -> 049.2024 | E37: ='REGIÃO 11 - HISTÓRICO'!C37 -> 47 | F37: Outubro | G37: ='REGIÃO 11 - HISTÓRICO'!D37 -> out/nov | H37: 207 | I37: =IF(tbResumoR11[[#This Row],[N° TRECHO]]="","",IFERROR(INDEX('REGIÃO 11 - TRECHOS'!$F$4:$F$119,MATCH(tbResumoR11[[#This Row],[N° TRECHO]],'REGIÃO 11 - TRECHOS'!$E$4:$E$119,0)),IFERROR(INDEX('REGIÃO 12 - TRECHOS'!$F$4:$F$76,MATCH(tbResumoR11[[#This Row],[N° TRECHO]],'REGIÃO 12 - TRECHOS'!$E$4:$E$76,0)),IFERROR(INDEX('REGIÃO 13 - TRECHOS'!$F$4:$F$53,MATCH(tbResumoR11[[#This Row],[N° TRECHO]],'REGIÃO 13 - TRECHOS'!$E$4:$E$53,0)),"Trecho não cadastrado")))) -> RODOVIA TO-181 - TRECHO ENTR. TO-255 - ENTR. TO-481 (CAPAO DO COCO) | J37: SERVIÇOS MANUTENÇÃO | K37: ='REGIÃO 11 - HISTÓRICO'!E37 -> 78662.67 | L37: ='REGIÃO 11 - HISTÓRICO'!I37 -> Em elaboração
B38: ='REGIÃO 11 - HISTÓRICO'!B38 -> 35 | C38: R11 | D38: =_xlfn.XLOOKUP(tbResumoR11[[#This Row],[REGIÃO]],tbRegioes[Código Região],tbRegioes[Contrato],"") -> 049.2024 | E38: ='REGIÃO 11 - HISTÓRICO'!C38 -> 48 | F38: Outubro | G38: ='REGIÃO 11 - HISTÓRICO'!D38 -> out | H38: 208 | I38: =IF(tbResumoR11[[#This Row],[N° TRECHO]]="","",IFERROR(INDEX('REGIÃO 11 - TRECHOS'!$F$4:$F$119,MATCH(tbResumoR11[[#This Row],[N° TRECHO]],'REGIÃO 11 - TRECHOS'!$E$4:$E$119,0)),IFERROR(INDEX('REGIÃO 12 - TRECHOS'!$F$4:$F$76,MATCH(tbResumoR11[[#This Row],[N° TRECHO]],'REGIÃO 12 - TRECHOS'!$E$4:$E$76,0)),IFERROR(INDEX('REGIÃO 13 - TRECHOS'!$F$4:$F$53,MATCH(tbResumoR11[[#This Row],[N° TRECHO]],'REGIÃO 13 - TRECHOS'!$E$4:$E$53,0)),"Trecho não cadastrado")))) -> RODOVIA TO-181 - TRECHO ENTR. TO-481 (CAPAO DO COCO) - FAZENDA COBRAPE | J38: SERVIÇOS MANUTENÇÃO | K38: ='REGIÃO 11 - HISTÓRICO'!E38 -> 2814.46 | L38: ='REGIÃO 11 - HISTÓRICO'!I38 -> Em elaboração
B39: ='REGIÃO 11 - HISTÓRICO'!B39 -> 36 | C39: R11 | D39: =_xlfn.XLOOKUP(tbResumoR11[[#This Row],[REGIÃO]],tbRegioes[Código Região],tbRegioes[Contrato],"") -> 049.2024 | E39: ='REGIÃO 11 - HISTÓRICO'!C39 -> 49 | F39: Outubro | G39: ='REGIÃO 11 - HISTÓRICO'!D39 -> out | H39: 210 | I39: =IF(tbResumoR11[[#This Row],[N° TRECHO]]="","",IFERROR(INDEX('REGIÃO 11 - TRECHOS'!$F$4:$F$119,MATCH(tbResumoR11[[#This Row],[N° TRECHO]],'REGIÃO 11 - TRECHOS'!$E$4:$E$119,0)),IFERROR(INDEX('REGIÃO 12 - TRECHOS'!$F$4:$F$76,MATCH(tbResumoR11[[#This Row],[N° TRECHO]],'REGIÃO 12 - TRECHOS'!$E$4:$E$76,0)),IFERROR(INDEX('REGIÃO 13 - TRECHOS'!$F$4:$F$53,MATCH(tbResumoR11[[#This Row],[N° TRECHO]],'REGIÃO 13 - TRECHOS'!$E$4:$E$53,0)),"Trecho não cadastrado")))) -> RODOVIA TO-181 - TRECHO ENTR. BR-242 - FUNDAÇÃO BRADESCO | J39: SERVIÇOS MANUTENÇÃO | K39: ='REGIÃO 11 - HISTÓRICO'!E39 -> 1154.46 | L39: ='REGIÃO 11 - HISTÓRICO'!I39 -> Em elaboração
B40: ='REGIÃO 11 - HISTÓRICO'!B37 -> 34 | C40: R11 | D40: =_xlfn.XLOOKUP(tbResumoR11[[#This Row],[REGIÃO]],tbRegioes[Código Região],tbRegioes[Contrato],"") -> 049.2024 | E40: ='REGIÃO 11 - HISTÓRICO'!C40 -> 50 | F40: Outubro | G40: ='REGIÃO 11 - HISTÓRICO'!D40 -> out | H40: 213 | I40: =IF(tbResumoR11[[#This Row],[N° TRECHO]]="","",IFERROR(INDEX('REGIÃO 11 - TRECHOS'!$F$4:$F$119,MATCH(tbResumoR11[[#This Row],[N° TRECHO]],'REGIÃO 11 - TRECHOS'!$E$4:$E$119,0)),IFERROR(INDEX('REGIÃO 12 - TRECHOS'!$F$4:$F$76,MATCH(tbResumoR11[[#This Row],[N° TRECHO]],'REGIÃO 12 - TRECHOS'!$E$4:$E$76,0)),IFERROR(INDEX('REGIÃO 13 - TRECHOS'!$F$4:$F$53,MATCH(tbResumoR11[[#This Row],[N° TRECHO]],'REGIÃO 13 - TRECHOS'!$E$4:$E$53,0)),"Trecho não cadastrado")))) -> RODOVIA TO-181 - TRECHO ARAGUAÇU - DIVISA TO-GO | J40: SERVIÇOS MANUTENÇÃO | K40: ='REGIÃO 11 - HISTÓRICO'!E40 -> 1064.44 | L40: ='REGIÃO 11 - HISTÓRICO'!I40 -> Em elaboração
B41: ='REGIÃO 11 - HISTÓRICO'!B38 -> 35 | C41: R11 | D41: =_xlfn.XLOOKUP(tbResumoR11[[#This Row],[REGIÃO]],tbRegioes[Código Região],tbRegioes[Contrato],"") -> 049.2024 | E41: ='REGIÃO 11 - HISTÓRICO'!C41 -> 51 | F41: Outubro | G41: ='REGIÃO 11 - HISTÓRICO'!D41 -> out/nov | H41: 202 | I41: =IF(tbResumoR11[[#This Row],[N° TRECHO]]="","",IFERROR(INDEX('REGIÃO 11 - TRECHOS'!$F$4:$F$119,MATCH(tbResumoR11[[#This Row],[N° TRECHO]],'REGIÃO 11 - TRECHOS'!$E$4:$E$119,0)),IFERROR(INDEX('REGIÃO 12 - TRECHOS'!$F$4:$F$76,MATCH(tbResumoR11[[#This Row],[N° TRECHO]],'REGIÃO 12 - TRECHOS'!$E$4:$E$76,0)),IFERROR(INDEX('REGIÃO 13 - TRECHOS'!$F$4:$F$53,MATCH(tbResumoR11[[#This Row],[N° TRECHO]],'REGIÃO 13 - TRECHOS'!$E$4:$E$53,0)),"Trecho não cadastrado")))) -> RODOVIA TO-070 - TRECHO SANDOLÂNDIA - FORMOSO DO ARAGUAIA | J41: SERVIÇOS MANUTENÇÃO | K41: ='REGIÃO 11 - HISTÓRICO'!E41 -> 6823.93 | L41: ='REGIÃO 11 - HISTÓRICO'!I41 -> Em elaboração
...

Sheet REGIÃO 11 - HISTÓRICO
